Workbook

Sheet Dashboard
B1: Invest Flex Vantage – Sum at Risk Analysis
B2: Client: female, non-smoker, entry age 74 · Income US Dividend and Growth Fund 100% · 5-year premium payment (MIP)
B4: Current scenario inputs | C4: Value
B5: Investment return (net of mgmt fee) | C5: =Inputs!$C$21 -> 0.08
B6: Dividend payout rate (cash scenario) | C6: =Inputs!$C$22 -> 0.08
B7: Annual premium | C7: =Inputs!$C$6 -> 24000
B8: Premium years | C8: =Inputs!$C$7 -> 5
B9: Total premiums | C9: =Inputs!$C$6*Inputs!$C$7 -> 120000
B10: Death benefit floor (101% of net premiums) | C10: =Inputs!$C$8*Inputs!$C$6*Inputs!$C$7 -> 121200
B11: COI rate multiplier | C11: =Inputs!$C$16 -> 1
B12: Years with a return override | C12: =COUNT('Return Path'!C5:C29) -> 0
B14: Key results | C14: Dividends reinvested | D14: Dividends paid out
B15: Age when sum at risk first triggers insurance charge | C15: =IFERROR(Inputs!$C$4+INDEX(Calc_Reinvest!$B$2:$B$301,MATCH(1,Calc_Reinvest!$S$2:$S$301,0))-1,"Never") -> Never | D15: =IFERROR(Inputs!$C$4+INDEX(Calc_Payout!$B$2:$B$301,MATCH(1,Calc_Payout!$S$2:$S$301,0))-1,"Never") -> 77
B16: Age when policy lapses (policy value hits $0) | C16: =IFERROR(Inputs!$C$4+INDEX(Calc_Reinvest!$B$2:$B$301,MATCH(1,Calc_Reinvest!$R$2:$R$301,0))-1,"No lapse to 99") -> No lapse to 99 | D16: =IFERROR(Inputs!$C$4+INDEX(Calc_Payout!$B$2:$B$301,MATCH(1,Calc_Payout!$R$2:$R$301,0))-1,"No lapse to 99") -> 93
B17: Total insurance charges (COI) to age 99 | C17: =SUM(Calc_Reinvest!M2:M301) -> 0 | D17: =SUM(Calc_Payout!M2:M301) -> 96105.262
B18: Largest sum at risk charged on | C18: =MAX(Calc_Reinvest!L2:L301) -> 0 | D18: =MAX(Calc_Payout!L2:L301) -> 120094.06
B19: Total dividends received in cash | C19: 0 | D19: =SUM(Calc_Payout!N2:N301) -> 116238.25
B20: Policy value at age 80 | C20: =IF(80-Inputs!$C$4<1,"n/a",INDEX(Calc_Reinvest!$Q$2:$Q$301,(80-Inputs!$C$4)*12)) -> 149416.85 | D20: =IF(80-Inputs!$C$4<1,"n/a",INDEX(Calc_Payout!$Q$2:$Q$301,(80-Inputs!$C$4)*12)) -> 107009.84
B21: Policy value at age 85 | C21: =IF(85-Inputs!$C$4<1,"n/a",INDEX(Calc_Reinvest!$Q$2:$Q$301,(85-Inputs!$C$4)*12)) -> 199420.28 | D21: =IF(85-Inputs!$C$4<1,"n/a",INDEX(Calc_Payout!$Q$2:$Q$301,(85-Inputs!$C$4)*12)) -> 87772.454
B22: Policy value at age 90 | C22: =IF(90-Inputs!$C$4<1,"n/a",INDEX(Calc_Reinvest!$Q$2:$Q$301,(90-Inputs!$C$4)*12)) -> 291532.05 | D22: =IF(90-Inputs!$C$4<1,"n/a",INDEX(Calc_Payout!$Q$2:$Q$301,(90-Inputs!$C$4)*12)) -> 59509.27
B23: Policy value at age 95 | C23: =IF(95-Inputs!$C$4<1,"n/a",INDEX(Calc_Reinvest!$Q$2:$Q$301,(95-Inputs!$C$4)*12)) -> 426190.05 | D23: =IF(95-Inputs!$C$4<1,"n/a",INDEX(Calc_Payout!$Q$2:$Q$301,(95-Inputs!$C$4)*12)) -> 0
B24: Policy value at age 99 | C24: =IF(99-Inputs!$C$4<1,"n/a",INDEX(Calc_Reinvest!$Q$2:$Q$301,(99-Inputs!$C$4)*12)) -> 577479.93 | D24: =IF(99-Inputs!$C$4<1,"n/a",INDEX(Calc_Payout!$Q$2:$Q$301,(99-Inputs!$C$4)*12)) -> 0
B26: How the sum at risk works
B27: =CONCATENATE("Sum at risk = 101% × net premiums ($",TEXT(Inputs!$C$8*Inputs!$C$6*Inputs!$C$7,"#,##0"),") − policy value. It only exists while the policy value is BELOW that floor.") -> Sum at risk = 101% × net premiums ($121,200) − policy value. It only exists while the policy value is BELOW that floor.
B28: =CONCATENATE("Years 1–10: policy fee ",TEXT(Inputs!$C$12,"0.0%")," + mgmt fee in model ",TEXT(Inputs!$C$14,"0.0%")," ≈ ",TEXT(Inputs!$C$12+Inputs!$C$14,"0.0%")," p.a. With dividends REINVESTED, a net return below ~this level shrinks the policy value toward/below the floor and SAR appears.") -> Years 1–10: policy fee 2.5% + mgmt fee in model 0.0% ≈ 2.5% p.a. With dividends REINVESTED, a net return below ~this level shrinks the policy value toward/below the floor and SAR appears.
B29: =CONCATENATE("With dividends PAID OUT at ",TEXT(Inputs!$C$22,"0%"),", the policy needs roughly ",TEXT(Inputs!$C$12+Inputs!$C$14+Inputs!$C$22,"0.0%")," net return (yrs 1–10) just to hold its value – otherwise it erodes, SAR grows and COI accelerates.") -> With dividends PAID OUT at 8%, the policy needs roughly 10.5% net return (yrs 1–10) just to hold its value – otherwise it erodes, SAR grows and COI accelerates.
B30: Payouts do NOT reduce net premiums (confirmed), so the $ floor stays fixed while the policy value falls – the gap is the sum at risk.
B31: COI rates per $1,000 SAR (female): age 80 $50.75 · age 85 $89.60 · age 90 $157.25 · age 95 $248.42 · age 99 $389.64 per year – i.e. 5%→39% of SAR p.a.

Sheet Inputs
B1: Invest Flex Vantage (VS2) – Inputs & Assumptions
B2: Blue text on yellow = change these. Everything else recalculates. Source references are to the Benefit Illustration (BI) dated 19/12/2024.
B3: Policy details
B4: Entry age (age last birthday at policy start) | C4: 74 | D4: BI p.2
B5: Gender (Male / Female) | C5: Female | D5: BI p.2 – selects COI rate column
B6: Annual regular premium ($) | C6: 24000 | D6: BI p.2 – $24,000 p.a. (paid at start of each policy year)
B7: Premium paying years (MIP) | C7: 5 | D7: BI p.2 – Minimum Investment Period 5 yrs; no premiums after
B8: Death benefit floor (% of net premiums) | C8: 1.01 | D8: Product Summary 3.1 – higher of 101% of net premiums or policy value
B9: Investment bonus (% of 1st-year premium) | C9: 0.04 | D9: Product Summary 2.2 – 4% for 5-yr MIP
B11: Charges
B12: Policy fee – policy years 1 to 10 (p.a. of policy value) | C12: 0.025 | D12: Product Summary 7.2
B13: Policy fee – policy year 11 onwards (p.a.) | C13: 0.006 | D13: Product Summary 7.2
B14: Fund management fee deducted by model (p.a.) | C14: 0 | D14: Set to 0% because the return you key in is already NET of the 1.50% fund management fee (Fund Summary). Enter 1.5% only if you key in gross returns
B15: Insurance cover charge (COI) starts after month | C15: 36 | D15: Product Summary 7.3 – from 3rd policy anniversary
B16: COI rate multiplier (stress test; 100% = current rates) | C16: 1 | D16: Rates are not guaranteed – raise to stress test
B17: Loyalty bonus (% of policy value, yearly) | C17: 0.005 | D17: Product Summary 2.3
B18: Loyalty bonus first paid at end of policy year | C18: 10 | D18: Product Summary 2.3 – from 10th anniversary
B19: Fund management fee used for BI Check only | C19: 0.015 | D19: BI illustrated rates (4%/8%) are before the 1.50% fee – used only on the BI Check sheet so it still reconciles to the BI
B20: Investment & dividend
B21: Investment return (p.a., NET of fund management fee) | C21: 0.08 | D21: Key in e.g. 8% or 5% – every column recalculates. Override any single year on the Return Path sheet
B22: Dividend payout rate (p.a. of fund value, paid monthly) | C22: 0.08 | D22: Fund currently distributes ~8% p.a. – not guaranteed. Used only in the "Dividend Paid Out" scenario
B24: Sensitivity return rates (net p.a.)
B25: Sensitivity rate 1 | C25: 0.02 | D25: Shown side by side on the Sensitivity sheet
B26: Sensitivity rate 2 | C26: 0.03
B27: Sensitivity rate 3 | C27: 0.04
B28: Sensitivity rate 4 | C28: 0.05
B29: Sensitivity rate 5 | C29: 0.06
B30: Sensitivity rate 6 | C30: 0.07
B31: Sensitivity rate 7 | C31: 0.08
B32: Sensitivity rate 8 | C32: 0.1

Sheet Return Path
A1: Year-by-year net return path (used by the main Projection & Dashboard)
A2: Leave Override blank to use the base return on Inputs. Type a rate (e.g. -15%) to model a bad year.
A4: Policy year | B4: Age at start (last b'day) | C4: Override return | D4: Return used
A5: 1 | B5: =Inputs!$C$4+A5-1 -> 74 | D5: =IF(C5="",Inputs!$C$21,C5) -> 0.08
A6: 2 | B6: =Inputs!$C$4+A6-1 -> 75 | D6: =IF(C6="",Inputs!$C$21,C6) -> 0.08
A7: 3 | B7: =Inputs!$C$4+A7-1 -> 76 | D7: =IF(C7="",Inputs!$C$21,C7) -> 0.08
A8: 4 | B8: =Inputs!$C$4+A8-1 -> 77 | D8: =IF(C8="",Inputs!$C$21,C8) -> 0.08
A9: 5 | B9: =Inputs!$C$4+A9-1 -> 78 | D9: =IF(C9="",Inputs!$C$21,C9) -> 0.08
A10: 6 | B10: =Inputs!$C$4+A10-1 -> 79 | D10: =IF(C10="",Inputs!$C$21,C10) -> 0.08
A11: 7 | B11: =Inputs!$C$4+A11-1 -> 80 | D11: =IF(C11="",Inputs!$C$21,C11) -> 0.08
A12: 8 | B12: =Inputs!$C$4+A12-1 -> 81 | D12: =IF(C12="",Inputs!$C$21,C12) -> 0.08
A13: 9 | B13: =Inputs!$C$4+A13-1 -> 82 | D13: =IF(C13="",Inputs!$C$21,C13) -> 0.08
A14: 10 | B14: =Inputs!$C$4+A14-1 -> 83 | D14: =IF(C14="",Inputs!$C$21,C14) -> 0.08
A15: 11 | B15: =Inputs!$C$4+A15-1 -> 84 | D15: =IF(C15="",Inputs!$C$21,C15) -> 0.08
A16: 12 | B16: =Inputs!$C$4+A16-1 -> 85 | D16: =IF(C16="",Inputs!$C$21,C16) -> 0.08
... A29: 25 | B29: =Inputs!$C$4+A29-1 -> 98 | D29: =IF(C29="",Inputs!$C$21,C29) -> 0.08

Sheet Projection
A1: Year-by-year projection – Dividends Reinvested vs Dividends Paid Out (cash)
A2: Values are end of policy year. Sum at risk (SAR) = 101% × net premiums − policy value (floor $0). Orange = SAR > 0 (insurance charges being deducted). Red = policy lapsed.
F3: DIVIDENDS REINVESTED (as in BI) | L3: DIVIDENDS PAID OUT AS CASH
A4: Policy year | B4: Age (end of year) | C4: Net return | D4: Premiums paid to date ($) | E4: Death benefit floor 101% ($) | F4: Policy value ($) | G4: Death benefit ($) | H4: Sum at risk ($) | I4: Insurance charge in year ($) | J4: Total charges in year ($) | K4: Surrender value ($) | L4: Policy value ($) | M4: Death benefit ($) | N4: Sum at risk ($) | O4: Insurance charge in year ($) | P4: Total charges in year ($) | Q4: Dividends received in year ($) | R4: Cumulative dividends ($) | S4: Policy value + cum. dividends ($) | T4: Status
A5: 1 | B5: =Inputs!$C$4+A5 -> 75 | C5: =INDEX('Return Path'!$D$5:$D$29,A5) -> 0.08 | D5: =Calc_Reinvest!I13 -> 24000 | E5: =Inputs!$C$8*D5 -> 24240 | F5: =Calc_Reinvest!Q13 -> 26290.549 | G5: =IF(Calc_Reinvest!R13=1,0,IF(A5=1,F5-SUMIFS(Calc_Reinvest!$H$2:$H$301,Calc_Reinvest!$B$2:$B$301,1),MAX(E5,F5))) -> 25330.549 | H5: =IF(OR(A5=1,Calc_Reinvest!R13=1),0,MAX(E5-F5,0)) -> 0 | I5: =SUMIFS(Calc_Reinvest!$M$2:$M$301,Calc_Reinvest!$B$2:$B$301,A5) -> 0 | J5: =SUMIFS(Calc_Reinvest!$M$2:$M$301,Calc_Reinvest!$B$2:$B$301,A5)+SUMIFS(Calc_Reinvest!$K$2:$K$301,Calc_Reinvest!$B$2:$B$301,A5) -> 643.21492 | K5: =F5*(1-INDEX(Rates!$F$4:$F$28,A5)) -> 0 | L5: =Calc_Payout!Q13 -> 24262.735 | M5: =IF(Calc_Payout!R13=1,0,IF(A5=1,L5-SUMIFS(Calc_Payout!$H$2:$H$301,Calc_Payout!$B$2:$B$301,1),MAX(E5,L5))) -> 23302.735 | N5: =IF(OR(A5=1,Calc_Payout!R13=1),0,MAX(E5-L5,0)) -> 0 | O5: =SUMIFS(Calc_Payout!$M$2:$M$301,Calc_Payout!$B$2:$B$301,A5) -> 0 | P5: =SUMIFS(Calc_Payout!$M$2:$M$301,Calc_Payout!$B$2:$B$301,A5)+SUMIFS(Calc_Payout!$K$2:$K$301,Calc_Payout!$B$2:$B$301,A5) -> 619.93281 | Q5: =SUMIFS(Calc_Payout!$N$2:$N$301,Calc_Payout!$B$2:$B$301,A5) -> 1979.6521 | R5: =Q5 -> 1979.6521 | S5: =L5+R5 -> 26242.387 | T5: =IF(Calc_Payout!R13=1,"LAPSED",IF(N5>0,"SAR active","OK")) -> OK
A6: 2 | B6: =Inputs!$C$4+A6 -> 76 | C6: =INDEX('Return Path'!$D$5:$D$29,A6) -> 0.08 | D6: =Calc_Reinvest!I25 -> 48000 | E6: =Inputs!$C$8*D6 -> 48480 | F6: =Calc_Reinvest!Q25 -> 52971.399 | G6: =IF(Calc_Reinvest!R25=1,0,IF(A6=1,F6-SUMIFS(Calc_Reinvest!$H$2:$H$301,Calc_Reinvest!$B$2:$B$301,1),MAX(E6,F6))) -> 52971.399 | H6: =IF(OR(A6=1,Calc_Reinvest!R25=1),0,MAX(E6-F6,0)) -> 0 | I6: =SUMIFS(Calc_Reinvest!$M$2:$M$301,Calc_Reinvest!$B$2:$B$301,A6) -> 0 | J6: =SUMIFS(Calc_Reinvest!$M$2:$M$301,Calc_Reinvest!$B$2:$B$301,A6)+SUMIFS(Calc_Reinvest!$K$2:$K$301,Calc_Reinvest!$B$2:$B$301,A6) -> 1295.9788 | K6: =F6*(1-INDEX(Rates!$F$4:$F$28,A6)) -> 0 | L6: =Calc_Payout!Q25 -> 46914.502 | M6: =IF(Calc_Payout!R25=1,0,IF(A6=1,L6-SUMIFS(Calc_Payout!$H$2:$H$301,Calc_Payout!$B$2:$B$301,1),MAX(E6,L6))) -> 48480 | N6: =IF(OR(A6=1,Calc_Payout!R25=1),0,MAX(E6-L6,0)) -> 1565.4978 | O6: =SUMIFS(Calc_Payout!$M$2:$M$301,Calc_Payout!$B$2:$B$301,A6) -> 0 | P6: =SUMIFS(Calc_Payout!$M$2:$M$301,Calc_Payout!$B$2:$B$301,A6)+SUMIFS(Calc_Payout!$K$2:$K$301,Calc_Payout!$B$2:$B$301,A6) -> 1198.704 | Q6: =SUMIFS(Calc_Payout!$N$2:$N$301,Calc_Payout!$B$2:$B$301,A6) -> 3827.8616 | R6: =R5+Q6 -> 5807.5137 | S6: =L6+R6 -> 52722.016 | T6: =IF(Calc_Payout!R25=1,"LAPSED",IF(N6>0,"SAR active","OK")) -> SAR active
A7: 3 | B7: =Inputs!$C$4+A7 -> 77 | C7: =INDEX('Return Path'!$D$5:$D$29,A7) -> 0.08 | D7: =Calc_Reinvest!I37 -> 72000 | E7: =Inputs!$C$8*D7 -> 72720 | F7: =Calc_Reinvest!Q37 -> 81074.531 | G7: =IF(Calc_Reinvest!R37=1,0,IF(A7=1,F7-SUMIFS(Calc_Reinvest!$H$2:$H$301,Calc_Reinvest!$B$2:$B$301,1),MAX(E7,F7))) -> 81074.531 | H7: =IF(OR(A7=1,Calc_Reinvest!R37=1),0,MAX(E7-F7,0)) -> 0 | I7: =SUMIFS(Calc_Reinvest!$M$2:$M$301,Calc_Reinvest!$B$2:$B$301,A7) -> 0 | J7: =SUMIFS(Calc_Reinvest!$M$2:$M$301,Calc_Reinvest!$B$2:$B$301,A7)+SUMIFS(Calc_Reinvest!$K$2:$K$301,Calc_Reinvest!$B$2:$B$301,A7) -> 1983.5398 | K7: =F7*(1-INDEX(Rates!$F$4:$F$28,A7)) -> 20268.633 | L7: =Calc_Payout!Q37 -> 68933.486 | M7: =IF(Calc_Payout!R37=1,0,IF(A7=1,L7-SUMIFS(Calc_Payout!$H$2:$H$301,Calc_Payout!$B$2:$B$301,1),MAX(E7,L7))) -> 72720 | N7: =IF(OR(A7=1,Calc_Payout!R37=1),0,MAX(E7-L7,0)) -> 3786.5144 | O7: =SUMIFS(Calc_Payout!$M$2:$M$301,Calc_Payout!$B$2:$B$301,A7) -> 0 | P7: =SUMIFS(Calc_Payout!$M$2:$M$301,Calc_Payout!$B$2:$B$301,A7)+SUMIFS(Calc_Payout!$K$2:$K$301,Calc_Payout!$B$2:$B$301,A7) -> 1761.3071 | Q7: =SUMIFS(Calc_Payout!$N$2:$N$301,Calc_Payout!$B$2:$B$301,A7) -> 5624.4408 | R7: =R6+Q7 -> 11431.954 | S7: =L7+R7 -> 80365.44 | T7: =IF(Calc_Payout!R37=1,"LAPSED",IF(N7>0,"SAR active","OK")) -> SAR active
A8: 4 | B8: =Inputs!$C$4+A8 -> 78 | C8: =INDEX('Return Path'!$D$5:$D$29,A8) -> 0.08 | D8: =Calc_Reinvest!I49 -> 96000 | E8: =Inputs!$C$8*D8 -> 96960 | F8: =Calc_Reinvest!Q49 -> 110675.76 | G8: =IF(Calc_Reinvest!R49=1,0,IF(A8=1,F8-SUMIFS(Calc_Reinvest!$H$2:$H$301,Calc_Reinvest!$B$2:$B$301,1),MAX(E8,F8))) -> 110675.76 | H8: =IF(OR(A8=1,Calc_Reinvest!R49=1),0,MAX(E8-F8,0)) -> 0 | I8: =SUMIFS(Calc_Reinvest!$M$2:$M$301,Calc_Reinvest!$B$2:$B$301,A8) -> 0 | J8: =SUMIFS(Calc_Reinvest!$M$2:$M$301,Calc_Reinvest!$B$2:$B$301,A8)+SUMIFS(Calc_Reinvest!$K$2:$K$301,Calc_Reinvest!$B$2:$B$301,A8) -> 2707.7527 | K8: =F8*(1-INDEX(Rates!$F$4:$F$28,A8)) -> 66405.459 | L8: =Calc_Payout!Q49 -> 90157.944 | M8: =IF(Calc_Payout!R49=1,0,IF(A8=1,L8-SUMIFS(Calc_Payout!$H$2:$H$301,Calc_Payout!$B$2:$B$301,1),MAX(E8,L8))) -> 96960 | N8: =IF(OR(A8=1,Calc_Payout!R49=1),0,MAX(E8-L8,0)) -> 6802.0558 | O8: =SUMIFS(Calc_Payout!$M$2:$M$301,Calc_Payout!$B$2:$B$301,A8) -> 182.73345 | P8: =SUMIFS(Calc_Payout!$M$2:$M$301,Calc_Payout!$B$2:$B$301,A8)+SUMIFS(Calc_Payout!$K$2:$K$301,Calc_Payout!$B$2:$B$301,A8) -> 2489.0628 | Q8: =SUMIFS(Calc_Payout!$N$2:$N$301,Calc_Payout!$B$2:$B$301,A8) -> 7363.6602 | R8: =R7+Q8 -> 18795.615 | S8: =L8+R8 -> 108953.56 | T8: =IF(Calc_Payout!R49=1,"LAPSED",IF(N8>0,"SAR active","OK")) -> SAR active
A9: 5 | B9: =Inputs!$C$4+A9 -> 79 | C9: =INDEX('Return Path'!$D$5:$D$29,A9) -> 0.08 | D9: =Calc_Reinvest!I61 -> 120000 | E9: =Inputs!$C$8*D9 -> 121200 | F9: =Calc_Reinvest!Q61 -> 141854.96 | G9: =IF(Calc_Reinvest!R61=1,0,IF(A9=1,F9-SUMIFS(Calc_Reinvest!$H$2:$H$301,Calc_Reinvest!$B$2:$B$301,1),MAX(E9,F9))) -> 141854.96 | H9: =IF(OR(A9=1,Calc_Reinvest!R61=1),0,MAX(E9-F9,0)) -> 0 | I9: =SUMIFS(Calc_Reinvest!$M$2:$M$301,Calc_Reinvest!$B$2:$B$301,A9) -> 0 | J9: =SUMIFS(Calc_Reinvest!$M$2:$M$301,Calc_Reinvest!$B$2:$B$301,A9)+SUMIFS(Calc_Reinvest!$K$2:$K$301,Calc_Reinvest!$B$2:$B$301,A9) -> 3470.5714 | K9: =F9*(1-INDEX(Rates!$F$4:$F$28,A9)) -> 113483.97 | L9: =Calc_Payout!Q61 -> 110633.99 | M9: =IF(Calc_Payout!R61=1,0,IF(A9=1,L9-SUMIFS(Calc_Payout!$H$2:$H$301,Calc_Payout!$B$2:$B$301,1),MAX(E9,L9))) -> 121200 | N9: =IF(OR(A9=1,Calc_Payout!R61=1),0,MAX(E9-L9,0)) -> 10566.015 | O9: =SUMIFS(Calc_Payout!$M$2:$M$301,Calc_Payout!$B$2:$B$301,A9) -> 341.22172 | P9: =SUMIFS(Calc_Payout!$M$2:$M$301,Calc_Payout!$B$2:$B$301,A9)+SUMIFS(Calc_Payout!$K$2:$K$301,Calc_Payout!$B$2:$B$301,A9) -> 3172.9924 | Q9: =SUMIFS(Calc_Payout!$N$2:$N$301,Calc_Payout!$B$2:$B$301,A9) -> 9040.513 | R9: =R8+Q9 -> 27836.128 | S9: =L9+R9 -> 138470.11 | T9: =IF(Calc_Payout!R61=1,"LAPSED",IF(N9>0,"SAR active","OK")) -> SAR active
A10: 6 | B10: =Inputs!$C$4+A10 -> 80 | C10: =INDEX('Return Path'!$D$5:$D$29,A10) -> 0.08 | D10: =Calc_Reinvest!I73 -> 120000 | E10: =Inputs!$C$8*D10 -> 121200 | F10: =Calc_Reinvest!Q73 -> 149416.85 | G10: =IF(Calc_Reinvest!R73=1,0,IF(A10=1,F10-SUMIFS(Calc_Reinvest!$H$2:$H$301,Calc_Reinvest!$B$2:$B$301,1),MAX(E10,F10))) -> 149416.85 | H10: =IF(OR(A10=1,Calc_Reinvest!R73=1),0,MAX(E10-F10,0)) -> 0 | I10: =SUMIFS(Calc_Reinvest!$M$2:$M$301,Calc_Reinvest!$B$2:$B$301,A10) -> 0 | J10: =SUMIFS(Calc_Reinvest!$M$2:$M$301,Calc_Reinvest!$B$2:$B$301,A10)+SUMIFS(Calc_Reinvest!$K$2:$K$301,Calc_Reinvest!$B$2:$B$301,A10) -> 3655.5779 | K10: =F10*(1-INDEX(Rates!$F$4:$F$28,A10)) -> 149416.85 | L10: =Calc_Payout!Q73 -> 107009.84 | M10: =IF(Calc_Payout!R73=1,0,IF(A10=1,L10-SUMIFS(Calc_Payout!$H$2:$H$301,Calc_Payout!$B$2:$B$301,1),MAX(E10,L10))) -> 121200 | N10: =IF(OR(A10=1,Calc_Payout!R73=1),0,MAX(E10-L10,0)) -> 14190.164 | O10: =SUMIFS(Calc_Payout!$M$2:$M$301,Calc_Payout!$B$2:$B$301,A10) -> 543.74635 | P10: =SUMIFS(Calc_Payout!$M$2:$M$301,Calc_Payout!$B$2:$B$301,A10)+SUMIFS(Calc_Payout!$K$2:$K$301,Calc_Payout!$B$2:$B$301,A10) -> 3285.7324 | Q10: =SUMIFS(Calc_Payout!$N$2:$N$301,Calc_Payout!$B$2:$B$301,A10) -> 8752.4505 | R10: =R9+Q10 -> 36588.578 | S10: =L10+R10 -> 143598.41 | T10: =IF(Calc_Payout!R73=1,"LAPSED",IF(N10>0,"SAR active","OK")) -> SAR active
A11: 7 | B11: =Inputs!$C$4+A11 -> 81 | C11: =INDEX('Return Path'!$D$5:$D$29,A11) -> 0.08 | D11: =Calc_Reinvest!I85 -> 120000 | E11: =Inputs!$C$8*D11 -> 121200 | F11: =Calc_Reinvest!Q85 -> 157381.85 | G11: =IF(Calc_Reinvest!R85=1,0,IF(A11=1,F11-SUMIFS(Calc_Reinvest!$H$2:$H$301,Calc_Reinvest!$B$2:$B$301,1),MAX(E11,F11))) -> 157381.85 | H11: =IF(OR(A11=1,Calc_Reinvest!R85=1),0,MAX(E11-F11,0)) -> 0 | I11: =SUMIFS(Calc_Reinvest!$M$2:$M$301,Calc_Reinvest!$B$2:$B$301,A11) -> 0 | J11: =SUMIFS(Calc_Reinvest!$M$2:$M$301,Calc_Reinvest!$B$2:$B$301,A11)+SUMIFS(Calc_Reinvest!$K$2:$K$301,Calc_Reinvest!$B$2:$B$301,A11) -> 3850.4467 | K11: =F11*(1-INDEX(Rates!$F$4:$F$28,A11)) -> 157381.85 | L11: =Calc_Payout!Q85 -> 103251.25 | M11: =IF(Calc_Payout!R85=1,0,IF(A11=1,L11-SUMIFS(Calc_Payout!$H$2:$H$301,Calc_Payout!$B$2:$B$301,1),MAX(E11,L11))) -> 121200 | N11: =IF(OR(A11=1,Calc_Payout!R85=1),0,MAX(E11-L11,0)) -> 17948.752 | O11: =SUMIFS(Calc_Payout!$M$2:$M$301,Calc_Payout!$B$2:$B$301,A11) -> 784.0479 | P11: =SUMIFS(Calc_Payout!$M$2:$M$301,Calc_Payout!$B$2:$B$301,A11)+SUMIFS(Calc_Payout!$K$2:$K$301,Calc_Payout!$B$2:$B$301,A11) -> 3433.3368 | Q11: =SUMIFS(Calc_Payout!$N$2:$N$301,Calc_Payout!$B$2:$B$301,A11) -> 8454.8354 | R11: =R10+Q11 -> 45043.414 | S11: =L11+R11 -> 148294.66 | T11: =IF(Calc_Payout!R85=1,"LAPSED",IF(N11>0,"SAR active","OK")) -> SAR active
A12: 8 | B12: =Inputs!$C$4+A12 -> 82 | C12: =INDEX('Return Path'!$D$5:$D$29,A12) -> 0.08 | D12: =Calc_Reinvest!I97 -> 120000 | E12: =Inputs!$C$8*D12 -> 121200 | F12: =Calc_Reinvest!Q97 -> 165771.44 | G12: =IF(Calc_Reinvest!R97=1,0,IF(A12=1,F12-SUMIFS(Calc_Reinvest!$H$2:$H$301,Calc_Reinvest!$B$2:$B$301,1),MAX(E12,F12))) -> 165771.44 | H12: =IF(OR(A12=1,Calc_Reinvest!R97=1),0,MAX(E12-F12,0)) -> 0 | I12: =SUMIFS(Calc_Reinvest!$M$2:$M$301,Calc_Reinvest!$B$2:$B$301,A12) -> 0 | J12: =SUMIFS(Calc_Reinvest!$M$2:$M$301,Calc_Reinvest!$B$2:$B$301,A12)+SUMIFS(Calc_Reinvest!$K$2:$K$301,Calc_Reinvest!$B$2:$B$301,A12) -> 4055.7034 | K12: =F12*(1-INDEX(Rates!$F$4:$F$28,A12)) -> 165771.44 | L12: =Calc_Payout!Q97 -> 99257.195 | M12: =IF(Calc_Payout!R97=1,0,IF(A12=1,L12-SUMIFS(Calc_Payout!$H$2:$H$301,Calc_Payout!$B$2:$B$301,1),MAX(E12,L12))) -> 121200 | N12: =IF(OR(A12=1,Calc_Payout!R97=1),0,MAX(E12-L12,0)) -> 21942.805 | O12: =SUMIFS(Calc_Payout!$M$2:$M$301,Calc_Payout!$B$2:$B$301,A12) -> 1131.1621 | P12: =SUMIFS(Calc_Payout!$M$2:$M$301,Calc_Payout!$B$2:$B$301,A12)+SUMIFS(Calc_Payout!$K$2:$K$301,Calc_Payout!$B$2:$B$301,A12) -> 3683.2415 | Q12: =SUMIFS(Calc_Payout!$N$2:$N$301,Calc_Payout!$B$2:$B$301,A12) -> 8142.0993 | R12: =R11+Q12 -> 53185.513 | S12: =L12+R12 -> 152442.71 | T12: =IF(Calc_Payout!R97=1,"LAPSED",IF(N12>0,"SAR active","OK")) -> SAR active
A13: 9 | B13: =Inputs!$C$4+A13 -> 83 | C13: =INDEX('Return Path'!$D$5:$D$29,A13) -> 0.08 | D13: =Calc_Reinvest!I109 -> 120000 | E13: =Inputs!$C$8*D13 -> 121200 | F13: =Calc_Reinvest!Q109 -> 174608.26 | G13: =IF(Calc_Reinvest!R109=1,0,IF(A13=1,F13-SUMIFS(Calc_Reinvest!$H$2:$H$301,Calc_Reinvest!$B$2:$B$301,1),MAX(E13,F13))) -> 174608.26 | H13: =IF(OR(A13=1,Calc_Reinvest!R109=1),0,MAX(E13-F13,0)) -> 0 | I13: =SUMIFS(Calc_Reinvest!$M$2:$M$301,Calc_Reinvest!$B$2:$B$301,A13) -> 0 | J13: =SUMIFS(Calc_Reinvest!$M$2:$M$301,Calc_Reinvest!$B$2:$B$301,A13)+SUMIFS(Calc_Reinvest!$K$2:$K$301,Calc_Reinvest!$B$2:$B$301,A13) -> 4271.9017 | K13: =F13*(1-INDEX(Rates!$F$4:$F$28,A13)) -> 174608.26 | L13: =Calc_Payout!Q109 -> 94957.678 | M13: =IF(Calc_Payout!R109=1,0,IF(A13=1,L13-SUMIFS(Calc_Payout!$H$2:$H$301,Calc_Payout!$B$2:$B$301,1),MAX(E13,L13))) -> 121200 | N13: =IF(OR(A13=1,Calc_Payout!R109=1),0,MAX(E13-L13,0)) -> 26242.322 | O13: =SUMIFS(Calc_Payout!$M$2:$M$301,Calc_Payout!$B$2:$B$301,A13) -> 1556.3538 | P13: =SUMIFS(Calc_Payout!$M$2:$M$301,Calc_Payout!$B$2:$B$301,A13)+SUMIFS(Calc_Payout!$K$2:$K$301,Calc_Payout!$B$2:$B$301,A13) -> 4004.5052 | Q13: =SUMIFS(Calc_Payout!$N$2:$N$301,Calc_Payout!$B$2:$B$301,A13) -> 7807.3877 | R13: =R12+Q13 -> 60992.901 | S13: =L13+R13 -> 155950.58 | T13: =IF(Calc_Payout!R109=1,"LAPSED",IF(N13>0,"SAR active","OK")) -> SAR active
A14: 10 | B14: =Inputs!$C$4+A14 -> 84 | C14: =INDEX('Return Path'!$D$5:$D$29,A14) -> 0.08 | D14: =Calc_Reinvest!I121 -> 120000 | E14: =Inputs!$C$8*D14 -> 121200 | F14: =Calc_Reinvest!Q121 -> 184835.73 | G14: =IF(Calc_Reinvest!R121=1,0,IF(A14=1,F14-SUMIFS(Calc_Reinvest!$H$2:$H$301,Calc_Reinvest!$B$2:$B$301,1),MAX(E14,F14))) -> 184835.73 | H14: =IF(OR(A14=1,Calc_Reinvest!R121=1),0,MAX(E14-F14,0)) -> 0 | I14: =SUMIFS(Calc_Reinvest!$M$2:$M$301,Calc_Reinvest!$B$2:$B$301,A14) -> 0 | J14: =SUMIFS(Calc_Reinvest!$M$2:$M$301,Calc_Reinvest!$B$2:$B$301,A14)+SUMIFS(Calc_Reinvest!$K$2:$K$301,Calc_Reinvest!$B$2:$B$301,A14) -> 4499.625 | K14: =F14*(1-INDEX(Rates!$F$4:$F$28,A14)) -> 184835.73 | L14: =Calc_Payout!Q121 -> 90724.467 | M14: =IF(Calc_Payout!R121=1,0,IF(A14=1,L14-SUMIFS(Calc_Payout!$H$2:$H$301,Calc_Payout!$B$2:$B$301,1),MAX(E14,L14))) -> 121200 | N14: =IF(OR(A14=1,Calc_Payout!R121=1),0,MAX(E14-L14,0)) -> 30475.533 | O14: =SUMIFS(Calc_Payout!$M$2:$M$301,Calc_Payout!$B$2:$B$301,A14) -> 2071.3959 | P14: =SUMIFS(Calc_Payout!$M$2:$M$301,Calc_Payout!$B$2:$B$301,A14)+SUMIFS(Calc_Payout!$K$2:$K$301,Calc_Payout!$B$2:$B$301,A14) -> 4407.0328 | Q14: =SUMIFS(Calc_Payout!$N$2:$N$301,Calc_Payout!$B$2:$B$301,A14) -> 7444.658 | R14: =R13+Q14 -> 68437.559 | S14: =L14+R14 -> 159162.03 | T14: =IF(Calc_Payout!R121=1,"LAPSED",IF(N14>0,"SAR active","OK")) -> SAR active
A15: 11 | B15: =Inputs!$C$4+A15 -> 85 | C15: =INDEX('Return Path'!$D$5:$D$29,A15) -> 0.08 | D15: =Calc_Reinvest!I133 -> 120000 | E15: =Inputs!$C$8*D15 -> 121200 | F15: =Calc_Reinvest!Q133 -> 199420.28 | G15: =IF(Calc_Reinvest!R133=1,0,IF(A15=1,F15-SUMIFS(Calc_Reinvest!$H$2:$H$301,Calc_Reinvest!$B$2:$B$301,1),MAX(E15,F15))) -> 199420.28 | H15: =IF(OR(A15=1,Calc_Reinvest!R133=1),0,MAX(E15-F15,0)) -> 0 | I15: =SUMIFS(Calc_Reinvest!$M$2:$M$301,Calc_Reinvest!$B$2:$B$301,A15) -> 0 | J15: =SUMIFS(Calc_Reinvest!$M$2:$M$301,Calc_Reinvest!$B$2:$B$301,A15)+SUMIFS(Calc_Reinvest!$K$2:$K$301,Calc_Reinvest!$B$2:$B$301,A15) -> 1153.2875 | K15: =F15*(1-INDEX(Rates!$F$4:$F$28,A15)) -> 199420.28 | L15: =Calc_Payout!Q133 -> 87772.454 | M15: =IF(Calc_Payout!R133=1,0,IF(A15=1,L15-SUMIFS(Calc_Payout!$H$2:$H$301,Calc_Payout!$B$2:$B$301,1),MAX(E15,L15))) -> 121200 | N15: =IF(OR(A15=1,Calc_Payout!R133=1),0,MAX(E15-L15,0)) -> 33427.546 | O15: =SUMIFS(Calc_Payout!$M$2:$M$301,Calc_Payout!$B$2:$B$301,A15) -> 2575.9632 | P15: =SUMIFS(Calc_Payout!$M$2:$M$301,Calc_Payout!$B$2:$B$301,A15)+SUMIFS(Calc_Payout!$K$2:$K$301,Calc_Payout!$B$2:$B$301,A15) -> 3114.5558 | Q15: =SUMIFS(Calc_Payout!$N$2:$N$301,Calc_Payout!$B$2:$B$301,A15) -> 7160.4711 | R15: =R14+Q15 -> 75598.03 | S15: =L15+R15 -> 163370.48 | T15: =IF(Calc_Payout!R133=1,"LAPSED",IF(N15>0,"SAR active","OK")) -> SAR active
A16: 12 | B16: =Inputs!$C$4+A16 -> 86 | C16: =INDEX('Return Path'!$D$5:$D$29,A16) -> 0.08 | D16: =Calc_Reinvest!I145 -> 120000 | E16: =Inputs!$C$8*D16 -> 121200 | F16: =Calc_Reinvest!Q145 -> 215155.63 | G16: =IF(Calc_Reinvest!R145=1,0,IF(A16=1,F16-SUMIFS(Calc_Reinvest!$H$2:$H$301,Calc_Reinvest!$B$2:$B$301,1),MAX(E16,F16))) -> 215155.63 | H16: =IF(OR(A16=1,Calc_Reinvest!R145=1),0,MAX(E16-F16,0)) -> 0 | I16: =SUMIFS(Calc_Reinvest!$M$2:$M$301,Calc_Reinvest!$B$2:$B$301,A16) -> 0 | J16: =SUMIFS(Calc_Reinvest!$M$2:$M$301,Calc_Reinvest!$B$2:$B$301,A16)+SUMIFS(Calc_Reinvest!$K$2:$K$301,Calc_Reinvest!$B$2:$B$301,A16) -> 1244.2882 | K16: =F16*(1-INDEX(Rates!$F$4:$F$28,A16)) -> 215155.63 | L16: =Calc_Payout!Q145 -> 84305.54 | M16: =IF(Calc_Payout!R145=1,0,IF(A16=1,L16-SUMIFS(Calc_Payout!$H$2:$H$301,Calc_Payout!$B$2:$B$301,1),MAX(E16,L16))) -> 121200 | N16: =IF(OR(A16=1,Calc_Payout!R145=1),0,MAX(E16-L16,0)) -> 36894.46 | O16: =SUMIFS(Calc_Payout!$M$2:$M$301,Calc_Payout!$B$2:$B$301,A16) -> 3106.694 | P16: =SUMIFS(Calc_Payout!$M$2:$M$301,Calc_Payout!$B$2:$B$301,A16)+SUMIFS(Calc_Payout!$K$2:$K$301,Calc_Payout!$B$2:$B$301,A16) -> 3626.1161 | Q16: =SUMIFS(Calc_Payout!$N$2:$N$301,Calc_Payout!$B$2:$B$301,A16) -> 6901.4548 | R16: =R15+Q16 -> 82499.484 | S16: =L16+R16 -> 166805.02 | T16: =IF(Calc_Payout!R145=1,"LAPSED",IF(N16>0,"SAR active","OK")) -> SAR active
A17: 13 | B17: =Inputs!$C$4+A17 -> 87 | C17: =INDEX('Return Path'!$D$5:$D$29,A17) -> 0.08 | D17: =Calc_Reinvest!I157 -> 120000 | E17: =Inputs!$C$8*D17 -> 121200 | F17: =Calc_Reinvest!Q157 -> 232132.59 | G17: =IF(Calc_Reinvest!R157=1,0,IF(A17=1,F17-SUMIFS(Calc_Reinvest!$H$2:$H$301,Calc_Reinvest!$B$2:$B$301,1),MAX(E17,F17))) -> 232132.59 | H17: =IF(OR(A17=1,Calc_Reinvest!R157=1),0,MAX(E17-F17,0)) -> 0 | I17: =SUMIFS(Calc_Reinvest!$M$2:$M$301,Calc_Reinvest!$B$2:$B$301,A17) -> 0 | J17: =SUMIFS(Calc_Reinvest!$M$2:$M$301,Calc_Reinvest!$B$2:$B$301,A17)+SUMIFS(Calc_Reinvest!$K$2:$K$301,Calc_Reinvest!$B$2:$B$301,A17) -> 1342.4693 | K17: =F17*(1-INDEX(Rates!$F$4:$F$28,A17)) -> 232132.59 | L17: =Calc_Payout!Q157 -> 79991.694 | M17: =IF(Calc_Payout!R157=1,0,IF(A17=1,L17-SUMIFS(Calc_Payout!$H$2:$H$301,Calc_Payout!$B$2:$B$301,1),MAX(E17,L17))) -> 121200 | N17: =IF(OR(A17=1,Calc_Payout!R157=1),0,MAX(E17-L17,0)) -> 41208.306 | O17: =SUMIFS(Calc_Payout!$M$2:$M$301,Calc_Payout!$B$2:$B$301,A17) -> 3973.6224 | P17: =SUMIFS(Calc_Payout!$M$2:$M$301,Calc_Payout!$B$2:$B$301,A17)+SUMIFS(Calc_Payout!$K$2:$K$301,Calc_Payout!$B$2:$B$301,A17) -> 4469.8891 | Q17: =SUMIFS(Calc_Payout!$N$2:$N$301,Calc_Payout!$B$2:$B$301,A17) -> 6587.091 | R17: =R16+Q17 -> 89086.575 | S17: =L17+R17 -> 169078.27 | T17: =IF(Calc_Payout!R157=1,"LAPSED",IF(N17>0,"SAR active","OK")) -> SAR active
A18: 14 | B18: =Inputs!$C$4+A18 -> 88 | C18: =INDEX('Return Path'!$D$5:$D$29,A18) -> 0.08 | D18: =Calc_Reinvest!I169 -> 120000 | E18: =Inputs!$C$8*D18 -> 121200 | F18: =Calc_Reinvest!Q169 -> 250449.12 | G18: =IF(Calc_Reinvest!R169=1,0,IF(A18=1,F18-SUMIFS(Calc_Reinvest!$H$2:$H$301,Calc_Reinvest!$B$2:$B$301,1),MAX(E18,F18))) -> 250449.12 | H18: =IF(OR(A18=1,Calc_Reinvest!R169=1),0,MAX(E18-F18,0)) -> 0 | I18: =SUMIFS(Calc_Reinvest!$M$2:$M$301,Calc_Reinvest!$B$2:$B$301,A18) -> 0 | J18: =SUMIFS(Calc_Reinvest!$M$2:$M$301,Calc_Reinvest!$B$2:$B$301,A18)+SUMIFS(Calc_Reinvest!$K$2:$K$301,Calc_Reinvest!$B$2:$B$301,A18) -> 1448.3975 | K18: =F18*(1-INDEX(Rates!$F$4:$F$28,A18)) -> 250449.12 | L18: =Calc_Payout!Q169 -> 74621.484 | M18: =IF(Calc_Payout!R169=1,0,IF(A18=1,L18-SUMIFS(Calc_Payout!$H$2:$H$301,Calc_Payout!$B$2:$B$301,1),MAX(E18,L18))) -> 121200 | N18: =IF(OR(A18=1,Calc_Payout!R169=1),0,MAX(E18-L18,0)) -> 46578.516 | O18: =SUMIFS(Calc_Payout!$M$2:$M$301,Calc_Payout!$B$2:$B$301,A18) -> 5054.8744 | P18: =SUMIFS(Calc_Payout!$M$2:$M$301,Calc_Payout!$B$2:$B$301,A18)+SUMIFS(Calc_Payout!$K$2:$K$301,Calc_Payout!$B$2:$B$301,A18) -> 5522.3283 | Q18: =SUMIFS(Calc_Payout!$N$2:$N$301,Calc_Payout!$B$2:$B$301,A18) -> 6195.9032 | R18: =R17+Q18 -> 95282.479 | S18: =L18+R18 -> 169903.96 | T18: =IF(Calc_Payout!R169=1,"LAPSED",IF(N18>0,"SAR active","OK")) -> SAR active
A19: 15 | B19: =Inputs!$C$4+A19 -> 89 | C19: =INDEX('Return Path'!$D$5:$D$29,A19) -> 0.08 | D19: =Calc_Reinvest!I181 -> 120000 | E19: =Inputs!$C$8*D19 -> 121200 | F19: =Calc_Reinvest!Q181 -> 270210.93 | G19: =IF(Calc_Reinvest!R181=1,0,IF(A19=1,F19-SUMIFS(Calc_Reinvest!$H$2:$H$301,Calc_Reinvest!$B$2:$B$301,1),MAX(E19,F19))) -> 270210.93 | H19: =IF(OR(A19=1,Calc_Reinvest!R181=1),0,MAX(E19-F19,0)) -> 0 | I19: =SUMIFS(Calc_Reinvest!$M$2:$M$301,Calc_Reinvest!$B$2:$B$301,A19) -> 0 | J19: =SUMIFS(Calc_Reinvest!$M$2:$M$301,Calc_Reinvest!$B$2:$B$301,A19)+SUMIFS(Calc_Reinvest!$K$2:$K$301,Calc_Reinvest!$B$2:$B$301,A19) -> 1562.684 | K19: =F19*(1-INDEX(Rates!$F$4:$F$28,A19)) -> 270210.93 | L19: =Calc_Payout!Q181 -> 67917.263 | M19: =IF(Calc_Payout!R181=1,0,IF(A19=1,L19-SUMIFS(Calc_Payout!$H$2:$H$301,Calc_Payout!$B$2:$B$301,1),MAX(E19,L19))) -> 121200 | N19: =IF(OR(A19=1,Calc_Payout!R181=1),0,MAX(E19-L19,0)) -> 53282.737 | O19: =SUMIFS(Calc_Payout!$M$2:$M$301,Calc_Payout!$B$2:$B$301,A19) -> 6419.9676 | P19: =SUMIFS(Calc_Payout!$M$2:$M$301,Calc_Payout!$B$2:$B$301,A19)+SUMIFS(Calc_Payout!$K$2:$K$301,Calc_Payout!$B$2:$B$301,A19) -> 6851.5096 | Q19: =SUMIFS(Calc_Payout!$N$2:$N$301,Calc_Payout!$B$2:$B$301,A19) -> 5708.2167 | R19: =R18+Q19 -> 100990.7 | S19: =L19+R19 -> 168907.96 | T19: =IF(Calc_Payout!R181=1,"LAPSED",IF(N19>0,"SAR active","OK")) -> SAR active
A20: 16 | B20: =Inputs!$C$4+A20 -> 90 | C20: =INDEX('Return Path'!$D$5:$D$29,A20) -> 0.08 | D20: =Calc_Reinvest!I193 -> 120000 | E20: =Inputs!$C$8*D20 -> 121200 | F20: =Calc_Reinvest!Q193 -> 291532.05 | G20: =IF(Calc_Reinvest!R193=1,0,IF(A20=1,F20-SUMIFS(Calc_Reinvest!$H$2:$H$301,Calc_Reinvest!$B$2:$B$301,1),MAX(E20,F20))) -> 291532.05 | H20: =IF(OR(A20=1,Calc_Reinvest!R193=1),0,MAX(E20-F20,0)) -> 0 | I20: =SUMIFS(Calc_Reinvest!$M$2:$M$301,Calc_Reinvest!$B$2:$B$301,A20) -> 0 | J20: =SUMIFS(Calc_Reinvest!$M$2:$M$301,Calc_Reinvest!$B$2:$B$301,A20)+SUMIFS(Calc_Reinvest!$K$2:$K$301,Calc_Reinvest!$B$2:$B$301,A20) -> 1685.9883 | K20: =F20*(1-INDEX(Rates!$F$4:$F$28,A20)) -> 291532.05 | L20: =Calc_Payout!Q193 -> 59509.27 | M20: =IF(Calc_Payout!R193=1,0,IF(A20=1,L20-SUMIFS(Calc_Payout!$H$2:$H$301,Calc_Payout!$B$2:$B$301,1),MAX(E20,L20))) -> 121200 | N20: =IF(OR(A20=1,Calc_Payout!R193=1),0,MAX(E20-L20,0)) -> 61690.73 | O20: =SUMIFS(Calc_Payout!$M$2:$M$301,Calc_Payout!$B$2:$B$301,A20) -> 8162.7512 | P20: =SUMIFS(Calc_Payout!$M$2:$M$301,Calc_Payout!$B$2:$B$301,A20)+SUMIFS(Calc_Payout!$K$2:$K$301,Calc_Payout!$B$2:$B$301,A20) -> 8549.3673 | Q20: =SUMIFS(Calc_Payout!$N$2:$N$301,Calc_Payout!$B$2:$B$301,A20) -> 5097.8849 | R20: =R19+Q20 -> 106088.58 | S20: =L20+R20 -> 165597.85 | T20: =IF(Calc_Payout!R193=1,"LAPSED",IF(N20>0,"SAR active","OK")) -> SAR active
A21: 17 | B21: =Inputs!$C$4+A21 -> 91 | C21: =INDEX('Return Path'!$D$5:$D$29,A21) -> 0.08 | D21: =Calc_Reinvest!I205 -> 120000 | E21: =Inputs!$C$8*D21 -> 121200 | F21: =Calc_Reinvest!Q205 -> 314535.53 | G21: =IF(Calc_Reinvest!R205=1,0,IF(A21=1,F21-SUMIFS(Calc_Reinvest!$H$2:$H$301,Calc_Reinvest!$B$2:$B$301,1),MAX(E21,F21))) -> 314535.53 | H21: =IF(OR(A21=1,Calc_Reinvest!R205=1),0,MAX(E21-F21,0)) -> 0 | I21: =SUMIFS(Calc_Reinvest!$M$2:$M$301,Calc_Reinvest!$B$2:$B$301,A21) -> 0 | J21: =SUMIFS(Calc_Reinvest!$M$2:$M$301,Calc_Reinvest!$B$2:$B$301,A21)+SUMIFS(Calc_Reinvest!$K$2:$K$301,Calc_Reinvest!$B$2:$B$301,A21) -> 1819.0221 | K21: =F21*(1-INDEX(Rates!$F$4:$F$28,A21)) -> 314535.53 | L21: =Calc_Payout!Q205 -> 48902.135 | M21: =IF(Calc_Payout!R205=1,0,IF(A21=1,L21-SUMIFS(Calc_Payout!$H$2:$H$301,Calc_Payout!$B$2:$B$301,1),MAX(E21,L21))) -> 121200 | N21: =IF(OR(A21=1,Calc_Payout!R205=1),0,MAX(E21-L21,0)) -> 72297.865 | O21: =SUMIFS(Calc_Payout!$M$2:$M$301,Calc_Payout!$B$2:$B$301,A21) -> 10411.167 | P21: =SUMIFS(Calc_Payout!$M$2:$M$301,Calc_Payout!$B$2:$B$301,A21)+SUMIFS(Calc_Payout!$K$2:$K$301,Calc_Payout!$B$2:$B$301,A21) -> 10741.286 | Q21: =SUMIFS(Calc_Payout!$N$2:$N$301,Calc_Payout!$B$2:$B$301,A21) -> 4329.9729 | R21: =R20+Q21 -> 110418.55 | S21: =L21+R21 -> 159320.69 | T21: =IF(Calc_Payout!R205=1,"LAPSED",IF(N21>0,"SAR active","OK")) -> SAR active
A22: 18 | B22: =Inputs!$C$4+A22 -> 92 | C22: =INDEX('Return Path'!$D$5:$D$29,A22) -> 0.08 | D22: =Calc_Reinvest!I217 -> 120000 | E22: =Inputs!$C$8*D22 -> 121200 | F22: =Calc_Reinvest!Q217 -> 339354.11 | G22: =IF(Calc_Reinvest!R217=1,0,IF(A22=1,F22-SUMIFS(Calc_Reinvest!$H$2:$H$301,Calc_Reinvest!$B$2:$B$301,1),MAX(E22,F22))) -> 339354.11 | H22: =IF(OR(A22=1,Calc_Reinvest!R217=1),0,MAX(E22-F22,0)) -> 0 | I22: =SUMIFS(Calc_Reinvest!$M$2:$M$301,Calc_Reinvest!$B$2:$B$301,A22) -> 0 | J22: =SUMIFS(Calc_Reinvest!$M$2:$M$301,Calc_Reinvest!$B$2:$B$301,A22)+SUMIFS(Calc_Reinvest!$K$2:$K$301,Calc_Reinvest!$B$2:$B$301,A22) -> 1962.5529 | K22: =F22*(1-INDEX(Rates!$F$4:$F$28,A22)) -> 339354.11 | L22: =Calc_Payout!Q217 -> 35032.777 | M22: =IF(Calc_Payout!R217=1,0,IF(A22=1,L22-SUMIFS(Calc_Payout!$H$2:$H$301,Calc_Payout!$B$2:$B$301,1),MAX(E22,L22))) -> 121200 | N22: =IF(OR(A22=1,Calc_Payout!R217=1),0,MAX(E22-L22,0)) -> 86167.223 | O22: =SUMIFS(Calc_Payout!$M$2:$M$301,Calc_Payout!$B$2:$B$301,A22) -> 13738.328 | P22: =SUMIFS(Calc_Payout!$M$2:$M$301,Calc_Payout!$B$2:$B$301,A22)+SUMIFS(Calc_Payout!$K$2:$K$301,Calc_Payout!$B$2:$B$301,A22) -> 13995.916 | Q22: =SUMIFS(Calc_Payout!$N$2:$N$301,Calc_Payout!$B$2:$B$301,A22) -> 3341.2119 | R22: =R21+Q22 -> 113759.77 | S22: =L22+R22 -> 148792.54 | T22: =IF(Calc_Payout!R217=1,"LAPSED",IF(N22>0,"SAR active","OK")) -> SAR active
A23: 19 | B23: =Inputs!$C$4+A23 -> 93 | C23: =INDEX('Return Path'!$D$5:$D$29,A23) -> 0.08 | D23: =Calc_Reinvest!I229 -> 120000 | E23: =Inputs!$C$8*D23 -> 121200 | F23: =Calc_Reinvest!Q229 -> 366131 | G23: =IF(Calc_Reinvest!R229=1,0,IF(A23=1,F23-SUMIFS(Calc_Reinvest!$H$2:$H$301,Calc_Reinvest!$B$2:$B$301,1),MAX(E23,F23))) -> 366131 | H23: =IF(OR(A23=1,Calc_Reinvest!R229=1),0,MAX(E23-F23,0)) -> 0 | I23: =SUMIFS(Calc_Reinvest!$M$2:$M$301,Calc_Reinvest!$B$2:$B$301,A23) -> 0 | J23: =SUMIFS(Calc_Reinvest!$M$2:$M$301,Calc_Reinvest!$B$2:$B$301,A23)+SUMIFS(Calc_Reinvest!$K$2:$K$301,Calc_Reinvest!$B$2:$B$301,A23) -> 2117.409 | K23: =F23*(1-INDEX(Rates!$F$4:$F$28,A23)) -> 366131 | L23: =Calc_Payout!Q229 -> 16750.11 | M23: =IF(Calc_Payout!R229=1,0,IF(A23=1,L23-SUMIFS(Calc_Payout!$H$2:$H$301,Calc_Payout!$B$2:$B$301,1),MAX(E23,L23))) -> 121200 | N23: =IF(OR(A23=1,Calc_Payout!R229=1),0,MAX(E23-L23,0)) -> 104449.89 | O23: =SUMIFS(Calc_Payout!$M$2:$M$301,Calc_Payout!$B$2:$B$301,A23) -> 18237.354 | P23: =SUMIFS(Calc_Payout!$M$2:$M$301,Calc_Payout!$B$2:$B$301,A23)+SUMIFS(Calc_Payout!$K$2:$K$301,Calc_Payout!$B$2:$B$301,A23) -> 18399.749 | Q23: =SUMIFS(Calc_Payout!$N$2:$N$301,Calc_Payout!$B$2:$B$301,A23) -> 2042.6003 | R23: =R22+Q23 -> 115802.37 | S23: =L23+R23 -> 132552.48 | T23: =IF(Calc_Payout!R229=1,"LAPSED",IF(N23>0,"SAR active","OK")) -> SAR active
A24: 20 | B24: =Inputs!$C$4+A24 -> 94 | C24: =INDEX('Return Path'!$D$5:$D$29,A24) -> 0.08 | D24: =Calc_Reinvest!I241 -> 120000 | E24: =Inputs!$C$8*D24 -> 121200 | F24: =Calc_Reinvest!Q241 -> 395020.75 | G24: =IF(Calc_Reinvest!R241=1,0,IF(A24=1,F24-SUMIFS(Calc_Reinvest!$H$2:$H$301,Calc_Reinvest!$B$2:$B$301,1),MAX(E24,F24))) -> 395020.75 | H24: =IF(OR(A24=1,Calc_Reinvest!R241=1),0,MAX(E24-F24,0)) -> 0 | I24: =SUMIFS(Calc_Reinvest!$M$2:$M$301,Calc_Reinvest!$B$2:$B$301,A24) -> 0 | J24: =SUMIFS(Calc_Reinvest!$M$2:$M$301,Calc_Reinvest!$B$2:$B$301,A24)+SUMIFS(Calc_Reinvest!$K$2:$K$301,Calc_Reinvest!$B$2:$B$301,A24) -> 2284.4842 | K24: =F24*(1-INDEX(Rates!$F$4:$F$28,A24)) -> 395020.75 | L24: =Calc_Payout!Q241 -> 0 | M24: =IF(Calc_Payout!R241=1,0,IF(A24=1,L24-SUMIFS(Calc_Payout!$H$2:$H$301,Calc_Payout!$B$2:$B$301,1),MAX(E24,L24))) -> 0 | N24: =IF(OR(A24=1,Calc_Payout!R241=1),0,MAX(E24-L24,0)) -> 0 | O24: =SUMIFS(Calc_Payout!$M$2:$M$301,Calc_Payout!$B$2:$B$301,A24) -> 17813.879 | P24: =SUMIFS(Calc_Payout!$M$2:$M$301,Calc_Payout!$B$2:$B$301,A24)+SUMIFS(Calc_Payout!$K$2:$K$301,Calc_Payout!$B$2:$B$301,A24) -> 17854.99 | Q24: =SUMIFS(Calc_Payout!$N$2:$N$301,Calc_Payout!$B$2:$B$301,A24) -> 435.88677 | R24: =R23+Q24 -> 116238.25 | S24: =L24+R24 -> 116238.25 | T24: =IF(Calc_Payout!R241=1,"LAPSED",IF(N24>0,"SAR active","OK")) -> LAPSED
A25: 21 | B25: =Inputs!$C$4+A25 -> 95 | C25: =INDEX('Return Path'!$D$5:$D$29,A25) -> 0.08 | D25: =Calc_Reinvest!I253 -> 120000 | E25: =Inputs!$C$8*D25 -> 121200 | F25: =Calc_Reinvest!Q253 -> 426190.05 | G25: =IF(Calc_Reinvest!R253=1,0,IF(A25=1,F25-SUMIFS(Calc_Reinvest!$H$2:$H$301,Calc_Reinvest!$B$2:$B$301,1),MAX(E25,F25))) -> 426190.05 | H25: =IF(OR(A25=1,Calc_Reinvest!R253=1),0,MAX(E25-F25,0)) -> 0 | I25: =SUMIFS(Calc_Reinvest!$M$2:$M$301,Calc_Reinvest!$B$2:$B$301,A25) -> 0 | J25: =SUMIFS(Calc_Reinvest!$M$2:$M$301,Calc_Reinvest!$B$2:$B$301,A25)+SUMIFS(Calc_Reinvest!$K$2:$K$301,Calc_Reinvest!$B$2:$B$301,A25) -> 2464.7425 | K25: =F25*(1-INDEX(Rates!$F$4:$F$28,A25)) -> 426190.05 | L25: =Calc_Payout!Q253 -> 0 | M25: =IF(Calc_Payout!R253=1,0,IF(A25=1,L25-SUMIFS(Calc_Payout!$H$2:$H$301,Calc_Payout!$B$2:$B$301,1),MAX(E25,L25))) -> 0 | N25: =IF(OR(A25=1,Calc_Payout!R253=1),0,MAX(E25-L25,0)) -> 0 | O25: =SUMIFS(Calc_Payout!$M$2:$M$301,Calc_Payout!$B$2:$B$301,A25) -> 0 | P25: =SUMIFS(Calc_Payout!$M$2:$M$301,Calc_Payout!$B$2:$B$301,A25)+SUMIFS(Calc_Payout!$K$2:$K$301,Calc_Payout!$B$2:$B$301,A25) -> 0 | Q25: =SUMIFS(Calc_Payout!$N$2:$N$301,Calc_Payout!$B$2:$B$301,A25) -> 0 | R25: =R24+Q25 -> 116238.25 | S25: =L25+R25 -> 116238.25 | T25: =IF(Calc_Payout!R253=1,"LAPSED",IF(N25>0,"SAR active","OK")) -> LAPSED
A26: 22 | B26: =Inputs!$C$4+A26 -> 96 | C26: =INDEX('Return Path'!$D$5:$D$29,A26) -> 0.08 | D26: =Calc_Reinvest!I265 -> 120000 | E26: =Inputs!$C$8*D26 -> 121200 | F26: =Calc_Reinvest!Q265 -> 459818.78 | G26: =IF(Calc_Reinvest!R265=1,0,IF(A26=1,F26-SUMIFS(Calc_Reinvest!$H$2:$H$301,Calc_Reinvest!$B$2:$B$301,1),MAX(E26,F26))) -> 459818.78 | H26: =IF(OR(A26=1,Calc_Reinvest!R265=1),0,MAX(E26-F26,0)) -> 0 | I26: =SUMIFS(Calc_Reinvest!$M$2:$M$301,Calc_Reinvest!$B$2:$B$301,A26) -> 0 | J26: =SUMIFS(Calc_Reinvest!$M$2:$M$301,Calc_Reinvest!$B$2:$B$301,A26)+SUMIFS(Calc_Reinvest!$K$2:$K$301,Calc_Reinvest!$B$2:$B$301,A26) -> 2659.2242 | K26: =F26*(1-INDEX(Rates!$F$4:$F$28,A26)) -> 459818.78 | L26: =Calc_Payout!Q265 -> 0 | M26: =IF(Calc_Payout!R265=1,0,IF(A26=1,L26-SUMIFS(Calc_Payout!$H$2:$H$301,Calc_Payout!$B$2:$B$301,1),MAX(E26,L26))) -> 0 | N26: =IF(OR(A26=1,Calc_Payout!R265=1),0,MAX(E26-L26,0)) -> 0 | O26: =SUMIFS(Calc_Payout!$M$2:$M$301,Calc_Payout!$B$2:$B$301,A26) -> 0 | P26: =SUMIFS(Calc_Payout!$M$2:$M$301,Calc_Payout!$B$2:$B$301,A26)+SUMIFS(Calc_Payout!$K$2:$K$301,Calc_Payout!$B$2:$B$301,A26) -> 0 | Q26: =SUMIFS(Calc_Payout!$N$2:$N$301,Calc_Payout!$B$2:$B$301,A26) -> 0 | R26: =R25+Q26 -> 116238.25 | S26: =L26+R26 -> 116238.25 | T26: =IF(Calc_Payout!R265=1,"LAPSED",IF(N26>0,"SAR active","OK")) -> LAPSED
A27: 23 | B27: =Inputs!$C$4+A27 -> 97 | C27: =INDEX('Return Path'!$D$5:$D$29,A27) -> 0.08 | D27: =Calc_Reinvest!I277 -> 120000 | E27: =Inputs!$C$8*D27 -> 121200 | F27: =Calc_Reinvest!Q277 -> 496101 | G27: =IF(Calc_Reinvest!R277=1,0,IF(A27=1,F27-SUMIFS(Calc_Reinvest!$H$2:$H$301,Calc_Reinvest!$B$2:$B$301,1),MAX(E27,F27))) -> 496101 | H27: =IF(OR(A27=1,Calc_Reinvest!R277=1),0,MAX(E27-F27,0)) -> 0 | I27: =SUMIFS(Calc_Reinvest!$M$2:$M$301,Calc_Reinvest!$B$2:$B$301,A27) -> 0 | J27: =SUMIFS(Calc_Reinvest!$M$2:$M$301,Calc_Reinvest!$B$2:$B$301,A27)+SUMIFS(Calc_Reinvest!$K$2:$K$301,Calc_Reinvest!$B$2:$B$301,A27) -> 2869.0516 | K27: =F27*(1-INDEX(Rates!$F$4:$F$28,A27)) -> 496101 | L27: =Calc_Payout!Q277 -> 0 | M27: =IF(Calc_Payout!R277=1,0,IF(A27=1,L27-SUMIFS(Calc_Payout!$H$2:$H$301,Calc_Payout!$B$2:$B$301,1),MAX(E27,L27))) -> 0 | N27: =IF(OR(A27=1,Calc_Payout!R277=1),0,MAX(E27-L27,0)) -> 0 | O27: =SUMIFS(Calc_Payout!$M$2:$M$301,Calc_Payout!$B$2:$B$301,A27) -> 0 | P27: =SUMIFS(Calc_Payout!$M$2:$M$301,Calc_Payout!$B$2:$B$301,A27)+SUMIFS(Calc_Payout!$K$2:$K$301,Calc_Payout!$B$2:$B$301,A27) -> 0 | Q27: =SUMIFS(Calc_Payout!$N$2:$N$301,Calc_Payout!$B$2:$B$301,A27) -> 0 | R27: =R26+Q27 -> 116238.25 | S27: =L27+R27 -> 116238.25 | T27: =IF(Calc_Payout!R277=1,"LAPSED",IF(N27>0,"SAR active","OK")) -> LAPSED
A28: 24 | B28: =Inputs!$C$4+A28 -> 98 | C28: =INDEX('Return Path'!$D$5:$D$29,A28) -> 0.08 | D28: =Calc_Reinvest!I289 -> 120000 | E28: =Inputs!$C$8*D28 -> 121200 | F28: =Calc_Reinvest!Q289 -> 535246.09 | G28: =IF(Calc_Reinvest!R289=1,0,IF(A28=1,F28-SUMIFS(Calc_Reinvest!$H$2:$H$301,Calc_Reinvest!$B$2:$B$301,1),MAX(E28,F28))) -> 535246.09 | H28: =IF(OR(A28=1,Calc_Reinvest!R289=1),0,MAX(E28-F28,0)) -> 0 | I28: =SUMIFS(Calc_Reinvest!$M$2:$M$301,Calc_Reinvest!$B$2:$B$301,A28) -> 0 | J28: =SUMIFS(Calc_Reinvest!$M$2:$M$301,Calc_Reinvest!$B$2:$B$301,A28)+SUMIFS(Calc_Reinvest!$K$2:$K$301,Calc_Reinvest!$B$2:$B$301,A28) -> 3095.4355 | K28: =F28*(1-INDEX(Rates!$F$4:$F$28,A28)) -> 535246.09 | L28: =Calc_Payout!Q289 -> 0 | M28: =IF(Calc_Payout!R289=1,0,IF(A28=1,L28-SUMIFS(Calc_Payout!$H$2:$H$301,Calc_Payout!$B$2:$B$301,1),MAX(E28,L28))) -> 0 | N28: =IF(OR(A28=1,Calc_Payout!R289=1),0,MAX(E28-L28,0)) -> 0 | O28: =SUMIFS(Calc_Payout!$M$2:$M$301,Calc_Payout!$B$2:$B$301,A28) -> 0 | P28: =SUMIFS(Calc_Payout!$M$2:$M$301,Calc_Payout!$B$2:$B$301,A28)+SUMIFS(Calc_Payout!$K$2:$K$301,Calc_Payout!$B$2:$B$301,A28) -> 0 | Q28: =SUMIFS(Calc_Payout!$N$2:$N$301,Calc_Payout!$B$2:$B$301,A28) -> 0 | R28: =R27+Q28 -> 116238.25 | S28: =L28+R28 -> 116238.25 | T28: =IF(Calc_Payout!R289=1,"LAPSED",IF(N28>0,"SAR active","OK")) -> LAPSED
A29: 25 | B29: =Inputs!$C$4+A29 -> 99 | C29: =INDEX('Return Path'!$D$5:$D$29,A29) -> 0.08 | D29: =Calc_Reinvest!I301 -> 120000 | E29: =Inputs!$C$8*D29 -> 121200 | F29: =Calc_Reinvest!Q301 -> 577479.93 | G29: =IF(Calc_Reinvest!R301=1,0,IF(A29=1,F29-SUMIFS(Calc_Reinvest!$H$2:$H$301,Calc_Reinvest!$B$2:$B$301,1),MAX(E29,F29))) -> 577479.93 | H29: =IF(OR(A29=1,Calc_Reinvest!R301=1),0,MAX(E29-F29,0)) -> 0 | I29: =SUMIFS(Calc_Reinvest!$M$2:$M$301,Calc_Reinvest!$B$2:$B$301,A29) -> 0 | J29: =SUMIFS(Calc_Reinvest!$M$2:$M$301,Calc_Reinvest!$B$2:$B$301,A29)+SUMIFS(Calc_Reinvest!$K$2:$K$301,Calc_Reinvest!$B$2:$B$301,A29) -> 3339.6823 | K29: =F29*(1-INDEX(Rates!$F$4:$F$28,A29)) -> 577479.93 | L29: =Calc_Payout!Q301 -> 0 | M29: =IF(Calc_Payout!R301=1,0,IF(A29=1,L29-SUMIFS(Calc_Payout!$H$2:$H$301,Calc_Payout!$B$2:$B$301,1),MAX(E29,L29))) -> 0 | N29: =IF(OR(A29=1,Calc_Payout!R301=1),0,MAX(E29-L29,0)) -> 0 | O29: =SUMIFS(Calc_Payout!$M$2:$M$301,Calc_Payout!$B$2:$B$301,A29) -> 0 | P29: =SUMIFS(Calc_Payout!$M$2:$M$301,Calc_Payout!$B$2:$B$301,A29)+SUMIFS(Calc_Payout!$K$2:$K$301,Calc_Payout!$B$2:$B$301,A29) -> 0 | Q29: =SUMIFS(Calc_Payout!$N$2:$N$301,Calc_Payout!$B$2:$B$301,A29) -> 0 | R29: =R28+Q29 -> 116238.25 | S29: =L29+R29 -> 116238.25 | T29: =IF(Calc_Payout!R301=1,"LAPSED",IF(N29>0,"SAR active","OK")) -> LAPSED
A31: Totals | I31: =SUM(I5:I29) -> 0 | J31: =SUM(J5:J29) -> 61483.031 | O31: =SUM(O5:O29) -> 96105.262 | P31: =SUM(P5:P29) -> 121181.56 | Q31: =SUM(Q5:Q29) -> 116238.25

Sheet Sensitivity
A1: Sensitivity – constant net return every year (rates set on Inputs C25:C32)
A3: Net return | B3: Scenario | C3: SAR first charged (age) | D3: Lapse age | E3: Total COI to 99 ($) | F3: Dividends received ($) | G3: PV age 80 ($) | H3: PV age 85 ($) | I3: PV age 90 ($) | J3: PV age 95 ($) | K3: PV age 99 ($)
A4: =Inputs!$C$25 -> 0.02 | B4: Reinvested | C4: =IFERROR(Inputs!$C$4+INDEX(S1_R!$B$2:$B$301,MATCH(1,S1_R!$S$2:$S$301,0))-1,"Never") -> 77 | D4: =IFERROR(Inputs!$C$4+INDEX(S1_R!$B$2:$B$301,MATCH(1,S1_R!$R$2:$R$301,0))-1,"No lapse to 99") -> No lapse to 99 | E4: =SUM(S1_R!M2:M301) -> 2387.5537 | F4: =SUM(S1_R!N2:N301) -> 0 | G4: =IF(80-Inputs!$C$4<1,"n/a",INDEX(S1_R!$Q$2:$Q$301,(80-Inputs!$C$4)*12)) -> 118212.55 | H4: =IF(85-Inputs!$C$4<1,"n/a",INDEX(S1_R!$Q$2:$Q$301,(85-Inputs!$C$4)*12)) -> 116876.99 | I4: =IF(90-Inputs!$C$4<1,"n/a",INDEX(S1_R!$Q$2:$Q$301,(90-Inputs!$C$4)*12)) -> 127853.8 | J4: =IF(95-Inputs!$C$4<1,"n/a",INDEX(S1_R!$Q$2:$Q$301,(95-Inputs!$C$4)*12)) -> 140447.08 | K4: =IF(99-Inputs!$C$4<1,"n/a",INDEX(S1_R!$Q$2:$Q$301,(99-Inputs!$C$4)*12)) -> 151409.1
A5: =Inputs!$C$25 -> 0.02 | B5: Paid out | C5: =IFERROR(Inputs!$C$4+INDEX(S1_P!$B$2:$B$301,MATCH(1,S1_P!$S$2:$S$301,0))-1,"Never") -> 77 | D5: =IFERROR(Inputs!$C$4+INDEX(S1_P!$B$2:$B$301,MATCH(1,S1_P!$R$2:$R$301,0))-1,"No lapse to 99") -> 88 | E5: =SUM(S1_P!M2:M301) -> 58230.468 | F5: =SUM(S1_P!N2:N301) -> 61827.611 | G5: =IF(80-Inputs!$C$4<1,"n/a",INDEX(S1_P!$Q$2:$Q$301,(80-Inputs!$C$4)*12)) -> 83682.07 | H5: =IF(85-Inputs!$C$4<1,"n/a",INDEX(S1_P!$Q$2:$Q$301,(85-Inputs!$C$4)*12)) -> 38369.977 | I5: =IF(90-Inputs!$C$4<1,"n/a",INDEX(S1_P!$Q$2:$Q$301,(90-Inputs!$C$4)*12)) -> 0 | J5: =IF(95-Inputs!$C$4<1,"n/a",INDEX(S1_P!$Q$2:$Q$301,(95-Inputs!$C$4)*12)) -> 0 | K5: =IF(99-Inputs!$C$4<1,"n/a",INDEX(S1_P!$Q$2:$Q$301,(99-Inputs!$C$4)*12)) -> 0
A6: =Inputs!$C$26 -> 0.03 | B6: Reinvested | C6: =IFERROR(Inputs!$C$4+INDEX(S2_R!$B$2:$B$301,MATCH(1,S2_R!$S$2:$S$301,0))-1,"Never") -> Never | D6: =IFERROR(Inputs!$C$4+INDEX(S2_R!$B$2:$B$301,MATCH(1,S2_R!$R$2:$R$301,0))-1,"No lapse to 99") -> No lapse to 99 | E6: =SUM(S2_R!M2:M301) -> 0 | F6: =SUM(S2_R!N2:N301) -> 0 | G6: =IF(80-Inputs!$C$4<1,"n/a",INDEX(S2_R!$Q$2:$Q$301,(80-Inputs!$C$4)*12)) -> 123184.53 | H6: =IF(85-Inputs!$C$4<1,"n/a",INDEX(S2_R!$Q$2:$Q$301,(85-Inputs!$C$4)*12)) -> 129715.91 | I6: =IF(90-Inputs!$C$4<1,"n/a",INDEX(S2_R!$Q$2:$Q$301,(90-Inputs!$C$4)*12)) -> 149615.84 | J6: =IF(95-Inputs!$C$4<1,"n/a",INDEX(S2_R!$Q$2:$Q$301,(95-Inputs!$C$4)*12)) -> 172568.66 | K6: =IF(99-Inputs!$C$4<1,"n/a",INDEX(S2_R!$Q$2:$Q$301,(99-Inputs!$C$4)*12)) -> 193441.39
A7: =Inputs!$C$26 -> 0.03 | B7: Paid out | C7: =IFERROR(Inputs!$C$4+INDEX(S2_P!$B$2:$B$301,MATCH(1,S2_P!$S$2:$S$301,0))-1,"Never") -> 77 | D7: =IFERROR(Inputs!$C$4+INDEX(S2_P!$B$2:$B$301,MATCH(1,S2_P!$R$2:$R$301,0))-1,"No lapse to 99") -> 88 | E7: =SUM(S2_P!M2:M301) -> 62457.918 | F7: =SUM(S2_P!N2:N301) -> 66712.931 | G7: =IF(80-Inputs!$C$4<1,"n/a",INDEX(S2_P!$Q$2:$Q$301,(80-Inputs!$C$4)*12)) -> 87248.523 | H7: =IF(85-Inputs!$C$4<1,"n/a",INDEX(S2_P!$Q$2:$Q$301,(85-Inputs!$C$4)*12)) -> 44911.91 | I7: =IF(90-Inputs!$C$4<1,"n/a",INDEX(S2_P!$Q$2:$Q$301,(90-Inputs!$C$4)*12)) -> 0 | J7: =IF(95-Inputs!$C$4<1,"n/a",INDEX(S2_P!$Q$2:$Q$301,(95-Inputs!$C$4)*12)) -> 0 | K7: =IF(99-Inputs!$C$4<1,"n/a",INDEX(S2_P!$Q$2:$Q$301,(99-Inputs!$C$4)*12)) -> 0
A8: =Inputs!$C$27 -> 0.04 | B8: Reinvested | C8: =IFERROR(Inputs!$C$4+INDEX(S3_R!$B$2:$B$301,MATCH(1,S3_R!$S$2:$S$301,0))-1,"Never") -> Never | D8: =IFERROR(Inputs!$C$4+INDEX(S3_R!$B$2:$B$301,MATCH(1,S3_R!$R$2:$R$301,0))-1,"No lapse to 99") -> No lapse to 99 | E8: =SUM(S3_R!M2:M301) -> 0 | F8: =SUM(S3_R!N2:N301) -> 0 | G8: =IF(80-Inputs!$C$4<1,"n/a",INDEX(S3_R!$Q$2:$Q$301,(80-Inputs!$C$4)*12)) -> 128081.5 | H8: =IF(85-Inputs!$C$4<1,"n/a",INDEX(S3_R!$Q$2:$Q$301,(85-Inputs!$C$4)*12)) -> 141548.11 | I8: =IF(90-Inputs!$C$4<1,"n/a",INDEX(S3_R!$Q$2:$Q$301,(90-Inputs!$C$4)*12)) -> 171344.03 | J8: =IF(95-Inputs!$C$4<1,"n/a",INDEX(S3_R!$Q$2:$Q$301,(95-Inputs!$C$4)*12)) -> 207412.01 | K8: =IF(99-Inputs!$C$4<1,"n/a",INDEX(S3_R!$Q$2:$Q$301,(99-Inputs!$C$4)*12)) -> 241660.58
A9: =Inputs!$C$27 -> 0.04 | B9: Paid out | C9: =IFERROR(Inputs!$C$4+INDEX(S3_P!$B$2:$B$301,MATCH(1,S3_P!$S$2:$S$301,0))-1,"Never") -> 77 | D9: =IFERROR(Inputs!$C$4+INDEX(S3_P!$B$2:$B$301,MATCH(1,S3_P!$R$2:$R$301,0))-1,"No lapse to 99") -> 89 | E9: =SUM(S3_P!M2:M301) -> 67495.516 | F9: =SUM(S3_P!N2:N301) -> 72505.846 | G9: =IF(80-Inputs!$C$4<1,"n/a",INDEX(S3_P!$Q$2:$Q$301,(80-Inputs!$C$4)*12)) -> 90938.709 | H9: =IF(85-Inputs!$C$4<1,"n/a",INDEX(S3_P!$Q$2:$Q$301,(85-Inputs!$C$4)*12)) -> 52064.365 | I9: =IF(90-Inputs!$C$4<1,"n/a",INDEX(S3_P!$Q$2:$Q$301,(90-Inputs!$C$4)*12)) -> 0 | J9: =IF(95-Inputs!$C$4<1,"n/a",INDEX(S3_P!$Q$2:$Q$301,(95-Inputs!$C$4)*12)) -> 0 | K9: =IF(99-Inputs!$C$4<1,"n/a",INDEX(S3_P!$Q$2:$Q$301,(99-Inputs!$C$4)*12)) -> 0
A10: =Inputs!$C$28 -> 0.05 | B10: Reinvested | C10: =IFERROR(Inputs!$C$4+INDEX(S4_R!$B$2:$B$301,MATCH(1,S4_R!$S$2:$S$301,0))-1,"Never") -> Never | D10: =IFERROR(Inputs!$C$4+INDEX(S4_R!$B$2:$B$301,MATCH(1,S4_R!$R$2:$R$301,0))-1,"No lapse to 99") -> No lapse to 99 | E10: =SUM(S4_R!M2:M301) -> 0 | F10: =SUM(S4_R!N2:N301) -> 0 | G10: =IF(80-Inputs!$C$4<1,"n/a",INDEX(S4_R!$Q$2:$Q$301,(80-Inputs!$C$4)*12)) -> 133148.16 | H10: =IF(85-Inputs!$C$4<1,"n/a",INDEX(S4_R!$Q$2:$Q$301,(85-Inputs!$C$4)*12)) -> 154359.23 | I10: =IF(90-Inputs!$C$4<1,"n/a",INDEX(S4_R!$Q$2:$Q$301,(90-Inputs!$C$4)*12)) -> 196009.59 | J10: =IF(95-Inputs!$C$4<1,"n/a",INDEX(S4_R!$Q$2:$Q$301,(95-Inputs!$C$4)*12)) -> 248898.36 | K10: =IF(99-Inputs!$C$4<1,"n/a",INDEX(S4_R!$Q$2:$Q$301,(99-Inputs!$C$4)*12)) -> 301312.95
A11: =Inputs!$C$28 -> 0.05 | B11: Paid out | C11: =IFERROR(Inputs!$C$4+INDEX(S4_P!$B$2:$B$301,MATCH(1,S4_P!$S$2:$S$301,0))-1,"Never") -> 77 | D11: =IFERROR(Inputs!$C$4+INDEX(S4_P!$B$2:$B$301,MATCH(1,S4_P!$R$2:$R$301,0))-1,"No lapse to 99") -> 90 | E11: =SUM(S4_P!M2:M301) -> 72717.002 | F11: =SUM(S4_P!N2:N301) -> 79534.908 | G11: =IF(80-Inputs!$C$4<1,"n/a",INDEX(S4_P!$Q$2:$Q$301,(80-Inputs!$C$4)*12)) -> 94756.218 | H11: =IF(85-Inputs!$C$4<1,"n/a",INDEX(S4_P!$Q$2:$Q$301,(85-Inputs!$C$4)*12)) -> 59874.556 | I11: =IF(90-Inputs!$C$4<1,"n/a",INDEX(S4_P!$Q$2:$Q$301,(90-Inputs!$C$4)*12)) -> 3183.3799 | J11: =IF(95-Inputs!$C$4<1,"n/a",INDEX(S4_P!$Q$2:$Q$301,(95-Inputs!$C$4)*12)) -> 0 | K11: =IF(99-Inputs!$C$4<1,"n/a",INDEX(S4_P!$Q$2:$Q$301,(99-Inputs!$C$4)*12)) -> 0
A12: =Inputs!$C$29 -> 0.06 | B12: Reinvested | C12: =IFERROR(Inputs!$C$4+INDEX(S5_R!$B$2:$B$301,MATCH(1,S5_R!$S$2:$S$301,0))-1,"Never") -> Never | D12: =IFERROR(Inputs!$C$4+INDEX(S5_R!$B$2:$B$301,MATCH(1,S5_R!$R$2:$R$301,0))-1,"No lapse to 99") -> No lapse to 99 | E12: =SUM(S5_R!M2:M301) -> 0 | F12: =SUM(S5_R!N2:N301) -> 0 | G12: =IF(80-Inputs!$C$4<1,"n/a",INDEX(S5_R!$Q$2:$Q$301,(80-Inputs!$C$4)*12)) -> 138389.5 | H12: =IF(85-Inputs!$C$4<1,"n/a",INDEX(S5_R!$Q$2:$Q$301,(85-Inputs!$C$4)*12)) -> 168222.24 | I12: =IF(90-Inputs!$C$4<1,"n/a",INDEX(S5_R!$Q$2:$Q$301,(90-Inputs!$C$4)*12)) -> 223980.88 | J12: =IF(95-Inputs!$C$4<1,"n/a",INDEX(S5_R!$Q$2:$Q$301,(95-Inputs!$C$4)*12)) -> 298221.19 | K12: =IF(99-Inputs!$C$4<1,"n/a",INDEX(S5_R!$Q$2:$Q$301,(99-Inputs!$C$4)*12)) -> 374973.46
A13: =Inputs!$C$29 -> 0.06 | B13: Paid out | C13: =IFERROR(Inputs!$C$4+INDEX(S5_P!$B$2:$B$301,MATCH(1,S5_P!$S$2:$S$301,0))-1,"Never") -> 77 | D13: =IFERROR(Inputs!$C$4+INDEX(S5_P!$B$2:$B$301,MATCH(1,S5_P!$R$2:$R$301,0))-1,"No lapse to 99") -> 91 | E13: =SUM(S5_P!M2:M301) -> 77478.13 | F13: =SUM(S5_P!N2:N301) -> 88342.321 | G13: =IF(80-Inputs!$C$4<1,"n/a",INDEX(S5_P!$Q$2:$Q$301,(80-Inputs!$C$4)*12)) -> 98704.723 | H13: =IF(85-Inputs!$C$4<1,"n/a",INDEX(S5_P!$Q$2:$Q$301,(85-Inputs!$C$4)*12)) -> 68392.873 | I13: =IF(90-Inputs!$C$4<1,"n/a",INDEX(S5_P!$Q$2:$Q$301,(90-Inputs!$C$4)*12)) -> 19136.644 | J13: =IF(95-Inputs!$C$4<1,"n/a",INDEX(S5_P!$Q$2:$Q$301,(95-Inputs!$C$4)*12)) -> 0 | K13: =IF(99-Inputs!$C$4<1,"n/a",INDEX(S5_P!$Q$2:$Q$301,(99-Inputs!$C$4)*12)) -> 0
A14: =Inputs!$C$30 -> 0.07 | B14: Reinvested | C14: =IFERROR(Inputs!$C$4+INDEX(S6_R!$B$2:$B$301,MATCH(1,S6_R!$S$2:$S$301,0))-1,"Never") -> Never | D14: =IFERROR(Inputs!$C$4+INDEX(S6_R!$B$2:$B$301,MATCH(1,S6_R!$R$2:$R$301,0))-1,"No lapse to 99") -> No lapse to 99 | E14: =SUM(S6_R!M2:M301) -> 0 | F14: =SUM(S6_R!N2:N301) -> 0 | G14: =IF(80-Inputs!$C$4<1,"n/a",INDEX(S6_R!$Q$2:$Q$301,(80-Inputs!$C$4)*12)) -> 143810.65 | H14: =IF(85-Inputs!$C$4<1,"n/a",INDEX(S6_R!$Q$2:$Q$301,(85-Inputs!$C$4)*12)) -> 183214.94 | I14: =IF(90-Inputs!$C$4<1,"n/a",INDEX(S6_R!$Q$2:$Q$301,(90-Inputs!$C$4)*12)) -> 255668.95 | J14: =IF(95-Inputs!$C$4<1,"n/a",INDEX(S6_R!$Q$2:$Q$301,(95-Inputs!$C$4)*12)) -> 356775.56 | K14: =IF(99-Inputs!$C$4<1,"n/a",INDEX(S6_R!$Q$2:$Q$301,(99-Inputs!$C$4)*12)) -> 465767.07
A15: =Inputs!$C$30 -> 0.07 | B15: Paid out | C15: =IFERROR(Inputs!$C$4+INDEX(S6_P!$B$2:$B$301,MATCH(1,S6_P!$S$2:$S$301,0))-1,"Never") -> 77 | D15: =IFERROR(Inputs!$C$4+INDEX(S6_P!$B$2:$B$301,MATCH(1,S6_P!$R$2:$R$301,0))-1,"No lapse to 99") -> 92 | E15: =SUM(S6_P!M2:M301) -> 86284.398 | F15: =SUM(S6_P!N2:N301) -> 99896.88 | G15: =IF(80-Inputs!$C$4<1,"n/a",INDEX(S6_P!$Q$2:$Q$301,(80-Inputs!$C$4)*12)) -> 102787.98 | H15: =IF(85-Inputs!$C$4<1,"n/a",INDEX(S6_P!$Q$2:$Q$301,(85-Inputs!$C$4)*12)) -> 77673.068 | I15: =IF(90-Inputs!$C$4<1,"n/a",INDEX(S6_P!$Q$2:$Q$301,(90-Inputs!$C$4)*12)) -> 37791.795 | J15: =IF(95-Inputs!$C$4<1,"n/a",INDEX(S6_P!$Q$2:$Q$301,(95-Inputs!$C$4)*12)) -> 0 | K15: =IF(99-Inputs!$C$4<1,"n/a",INDEX(S6_P!$Q$2:$Q$301,(99-Inputs!$C$4)*12)) -> 0
A16: =Inputs!$C$31 -> 0.08 | B16: Reinvested | C16: =IFERROR(Inputs!$C$4+INDEX(S7_R!$B$2:$B$301,MATCH(1,S7_R!$S$2:$S$301,0))-1,"Never") -> Never | D16: =IFERROR(Inputs!$C$4+INDEX(S7_R!$B$2:$B$301,MATCH(1,S7_R!$R$2:$R$301,0))-1,"No lapse to 99") -> No lapse to 99 | E16: =SUM(S7_R!M2:M301) -> 0 | F16: =SUM(S7_R!N2:N301) -> 0 | G16: =IF(80-Inputs!$C$4<1,"n/a",INDEX(S7_R!$Q$2:$Q$301,(80-Inputs!$C$4)*12)) -> 149416.85 | H16: =IF(85-Inputs!$C$4<1,"n/a",INDEX(S7_R!$Q$2:$Q$301,(85-Inputs!$C$4)*12)) -> 199420.28 | I16: =IF(90-Inputs!$C$4<1,"n/a",INDEX(S7_R!$Q$2:$Q$301,(90-Inputs!$C$4)*12)) -> 291532.05 | J16: =IF(95-Inputs!$C$4<1,"n/a",INDEX(S7_R!$Q$2:$Q$301,(95-Inputs!$C$4)*12)) -> 426190.05 | K16: =IF(99-Inputs!$C$4<1,"n/a",INDEX(S7_R!$Q$2:$Q$301,(99-Inputs!$C$4)*12)) -> 577479.93
A17: =Inputs!$C$31 -> 0.08 | B17: Paid out | C17: =IFERROR(Inputs!$C$4+INDEX(S7_P!$B$2:$B$301,MATCH(1,S7_P!$S$2:$S$301,0))-1,"Never") -> 77 | D17: =IFERROR(Inputs!$C$4+INDEX(S7_P!$B$2:$B$301,MATCH(1,S7_P!$R$2:$R$301,0))-1,"No lapse to 99") -> 93 | E17: =SUM(S7_P!M2:M301) -> 96105.262 | F17: =SUM(S7_P!N2:N301) -> 116238.25 | G17: =IF(80-Inputs!$C$4<1,"n/a",INDEX(S7_P!$Q$2:$Q$301,(80-Inputs!$C$4)*12)) -> 107009.84 | H17: =IF(85-Inputs!$C$4<1,"n/a",INDEX(S7_P!$Q$2:$Q$301,(85-Inputs!$C$4)*12)) -> 87772.454 | I17: =IF(90-Inputs!$C$4<1,"n/a",INDEX(S7_P!$Q$2:$Q$301,(90-Inputs!$C$4)*12)) -> 59509.27 | J17: =IF(95-Inputs!$C$4<1,"n/a",INDEX(S7_P!$Q$2:$Q$301,(95-Inputs!$C$4)*12)) -> 0 | K17: =IF(99-Inputs!$C$4<1,"n/a",INDEX(S7_P!$Q$2:$Q$301,(99-Inputs!$C$4)*12)) -> 0
A18: =Inputs!$C$32 -> 0.1 | B18: Reinvested | C18: =IFERROR(Inputs!$C$4+INDEX(S8_R!$B$2:$B$301,MATCH(1,S8_R!$S$2:$S$301,0))-1,"Never") -> Never | D18: =IFERROR(Inputs!$C$4+INDEX(S8_R!$B$2:$B$301,MATCH(1,S8_R!$R$2:$R$301,0))-1,"No lapse to 99") -> No lapse to 99 | E18: =SUM(S8_R!M2:M301) -> 0 | F18: =SUM(S8_R!N2:N301) -> 0 | G18: =IF(80-Inputs!$C$4<1,"n/a",INDEX(S8_R!$Q$2:$Q$301,(80-Inputs!$C$4)*12)) -> 161206.01 | H18: =IF(85-Inputs!$C$4<1,"n/a",INDEX(S8_R!$Q$2:$Q$301,(85-Inputs!$C$4)*12)) -> 235828.13 | I18: =IF(90-Inputs!$C$4<1,"n/a",INDEX(S8_R!$Q$2:$Q$301,(90-Inputs!$C$4)*12)) -> 377882.91 | J18: =IF(95-Inputs!$C$4<1,"n/a",INDEX(S8_R!$Q$2:$Q$301,(95-Inputs!$C$4)*12)) -> 605506.61 | K18: =IF(99-Inputs!$C$4<1,"n/a",INDEX(S8_R!$Q$2:$Q$301,(99-Inputs!$C$4)*12)) -> 882933.93
A19: =Inputs!$C$32 -> 0.1 | B19: Paid out | C19: =IFERROR(Inputs!$C$4+INDEX(S8_P!$B$2:$B$301,MATCH(1,S8_P!$S$2:$S$301,0))-1,"Never") -> 77 | D19: =IFERROR(Inputs!$C$4+INDEX(S8_P!$B$2:$B$301,MATCH(1,S8_P!$R$2:$R$301,0))-1,"No lapse to 99") -> No lapse to 99 | E19: =SUM(S8_P!M2:M301) -> 15255.142 | F19: =SUM(S8_P!N2:N301) -> 212935.47 | G19: =IF(80-Inputs!$C$4<1,"n/a",INDEX(S8_P!$Q$2:$Q$301,(80-Inputs!$C$4)*12)) -> 115885.14 | H19: =IF(85-Inputs!$C$4<1,"n/a",INDEX(S8_P!$Q$2:$Q$301,(85-Inputs!$C$4)*12)) -> 110677.09 | I19: =IF(90-Inputs!$C$4<1,"n/a",INDEX(S8_P!$Q$2:$Q$301,(90-Inputs!$C$4)*12)) -> 113789.43 | J19: =IF(95-Inputs!$C$4<1,"n/a",INDEX(S8_P!$Q$2:$Q$301,(95-Inputs!$C$4)*12)) -> 116777.15 | K19: =IF(99-Inputs!$C$4<1,"n/a",INDEX(S8_P!$Q$2:$Q$301,(99-Inputs!$C$4)*12)) -> 121246.54

Sheet BI Check
A1: Calibration – model vs Benefit Illustration supplementary illustration (premiums stop after MIP), dividends reinvested
A2: BI figures typed from BI pp.7–8 (Non-guaranteed policy value). Valid only while Inputs match the BI (age 74 F, $24,000 × 5 yrs, current charges).
A4: Policy year | B4: Age | C4: BI @4% ($) | D4: Model @4% ($) | E4: Diff % | F4: BI @8% ($) | G4: Model @8% ($) | H4: Diff %
A5: 1 | B5: =Inputs!$C$4+A5 -> 75 | C5: 24942 | D5: =Calc_BI4!Q13 -> 24938.89 | E5: =D5/C5-1 -> -0.00012468026 | F5: 25902 | G5: =Calc_BI8!Q13 -> 25898.078 | H5: =G5/F5-1 -> -0.00015140489
A6: 2 | B6: =Inputs!$C$4+A6 -> 76 | C6: 48907 | D6: =Calc_BI4!Q25 -> 48897.5 | E6: =D6/C6-1 -> -0.00019423716 | F6: 51784 | G6: =Calc_BI8!Q25 -> 51773.411 | H6: =G6/F6-1 -> -0.00020448318
A7: 3 | B7: =Inputs!$C$4+A7 -> 77 | C7: 72855 | D7: =Calc_BI4!Q37 -> 72835.848 | E7: =D7/C7-1 -> -0.00026288099 | F7: 78643 | G7: =Calc_BI8!Q37 -> 78621.223 | H7: =G7/F7-1 -> -0.00027690602
A8: 4 | B8: =Inputs!$C$4+A8 -> 78 | C8: 96781 | D8: =Calc_BI4!Q49 -> 96747.567 | E8: =D8/C8-1 -> -0.00034545065 | F8: 106515 | G8: =Calc_BI8!Q49 -> 106478.06 | H8: =G8/F8-1 -> -0.00034676829
A9: 5 | B9: =Inputs!$C$4+A9 -> 79 | C9: 120676 | D9: =Calc_BI4!Q61 -> 120623.84 | E9: =D9/C9-1 -> -0.00043224636 | F9: 135438 | G9: =Calc_BI8!Q61 -> 135381.86 | H9: =G9/F9-1 -> -0.00041453864
A10: 6 | B10: =Inputs!$C$4+A10 -> 80 | C10: 120563 | D10: =Calc_BI4!Q73 -> 120492 | E10: =D10/C10-1 -> -0.00058889793 | F10: 140547 | G10: =Calc_BI8!Q73 -> 140469.95 | H10: =G10/F10-1 -> -0.00054822968
A11: 7 | B11: =Inputs!$C$4+A11 -> 81 | C11: 120442 | D11: =Calc_BI4!Q85 -> 120350.49 | E11: =D11/C11-1 -> -0.0007598165 | F11: 145848 | G11: =Calc_BI8!Q85 -> 145749.27 | H11: =G11/F11-1 -> -0.00067695592
A12: 8 | B12: =Inputs!$C$4+A12 -> 82 | C12: 120308 | D12: =Calc_BI4!Q97 -> 120194.37 | E12: =D12/C12-1 -> -0.00094451582 | F12: 151350 | G12: =Calc_BI8!Q97 -> 151227 | H12: =G12/F12-1 -> -0.00081268077
A13: 9 | B13: =Inputs!$C$4+A13 -> 83 | C13: 120159 | D13: =Calc_BI4!Q109 -> 120020.29 | E13: =D13/C13-1 -> -0.0011543928 | F13: 157059 | G13: =Calc_BI8!Q109 -> 156910.61 | H13: =G13/F13-1 -> -0.00094483406
A14: 10 | B14: =Inputs!$C$4+A14 -> 84 | C14: 120590 | D14: =Calc_BI4!Q121 -> 120423.38 | E14: =D14/C14-1 -> -0.001381726 | F14: 163799 | G14: =Calc_BI8!Q121 -> 163621.86 | H14: =G14/F14-1 -> -0.0010814635
A15: 11 | B15: =Inputs!$C$4+A15 -> 85 | C15: 123424 | D15: =Calc_BI4!Q133 -> 123239.6 | E15: =D15/C15-1 -> -0.001494067 | F15: 174109 | G15: =Calc_BI8!Q133 -> 173901.35 | H15: =G15/F15-1 -> -0.0011926242
A16: 12 | B16: =Inputs!$C$4+A16 -> 86 | C16: 126333 | D16: =Calc_BI4!Q145 -> 126130.9 | E16: =D16/C16-1 -> -0.0015997409 | F16: 185067 | G16: =Calc_BI8!Q145 -> 184826.66 | H16: =G16/F16-1 -> -0.0012986876
A17: 13 | B17: =Inputs!$C$4+A17 -> 87 | C17: 129311 | D17: =Calc_BI4!Q157 -> 129090.04 | E17: =D17/C17-1 -> -0.0017087798 | F17: 196716 | G17: =Calc_BI8!Q157 -> 196438.34 | H17: =G17/F17-1 -> -0.0014114909
A18: 14 | B18: =Inputs!$C$4+A18 -> 88 | C18: 132360 | D18: =Calc_BI4!Q169 -> 132118.6 | E18: =D18/C18-1 -> -0.0018238454 | F18: 209097 | G18: =Calc_BI8!Q169 -> 208779.52 | H18: =G18/F18-1 -> -0.0015183429
A19: 15 | B19: =Inputs!$C$4+A19 -> 89 | C19: 135480 | D19: =Calc_BI4!Q181 -> 135218.21 | E19: =D19/C19-1 -> -0.001932328 | F19: 222258 | G19: =Calc_BI8!Q181 -> 221896.03 | H19: =G19/F19-1 -> -0.001628593
A20: 16 | B20: =Inputs!$C$4+A20 -> 90 | C20: 138673 | D20: =Calc_BI4!Q193 -> 138390.54 | E20: =D20/C20-1 -> -0.0020368776 | F20: 236247 | G20: =Calc_BI8!Q193 -> 235836.59 | H20: =G20/F20-1 -> -0.0017372224
A21: 17 | B21: =Inputs!$C$4+A21 -> 91 | C21: 141942 | D21: =Calc_BI4!Q205 -> 141637.3 | E21: =D21/C21-1 -> -0.0021466691 | F21: 251117 | G21: =Calc_BI8!Q205 -> 250652.95 | H21: =G21/F21-1 -> -0.0018479355
A22: 18 | B22: =Inputs!$C$4+A22 -> 92 | C22: 145288 | D22: =Calc_BI4!Q217 -> 144960.23 | E22: =D22/C22-1 -> -0.0022560256 | F22: 266923 | G22: =Calc_BI8!Q217 -> 266400.15 | H22: =G22/F22-1 -> -0.0019587992
A23: 19 | B23: =Inputs!$C$4+A23 -> 93 | C23: 148713 | D23: =Calc_BI4!Q229 -> 148361.11 | E23: =D23/C23-1 -> -0.0023662067 | F23: 283723 | G23: =Calc_BI8!Q229 -> 283136.66 | H23: =G23/F23-1 -> -0.0020665784
